2018-09-27 08:40:22,466 - Not Found: /img/favicon.png
2018-09-27 08:49:15,173 - Internal Server Error: /getAllPlans
Traceback (most recent call last):
  File "C:\Users\Administrator\venv\lib\site-packages\django\core\handlers\exception.py", line 34, in inner
    response = get_response(request)
  File "C:\Users\Administrator\venv\lib\site-packages\django\core\handlers\base.py", line 126, in _get_response
    response = self.process_exception_by_middleware(e, request)
  File "C:\Users\Administrator\venv\lib\site-packages\django\core\handlers\base.py", line 124, in _get_response
    response = wrapped_callback(request, *callback_args, **callback_kwargs)
  File "D:\项目汇总\kanban\basics\views\plan.py", line 40, in getAllPlans
    if list(assys)[0][0]:
IndexError: list index out of range
2018-09-25 08:49:34,155 - Internal Server Error: /getAllPlans
Traceback (most recent call last):
  File "C:\Users\Administrator\venv\lib\site-packages\django\core\handlers\exception.py", line 34, in inner
    response = get_response(request)
  File "C:\Users\Administrator\venv\lib\site-packages\django\core\handlers\base.py", line 126, in _get_response
    response = self.process_exception_by_middleware(e, request)
  File "C:\Users\Administrator\venv\lib\site-packages\django\core\handlers\base.py", line 124, in _get_response
    response = wrapped_callback(request, *callback_args, **callback_kwargs)
  File "D:\项目汇总\kanban\basics\views\plan.py", line 40, in getAllPlans
    if list(assys)[0][0]:
IndexError: list index out of range
2018-09-25 08:55:33,851 - Internal Server Error: /getAllPlans
Traceback (most recent call last):
  File "C:\Users\Administrator\venv\lib\site-packages\django\core\handlers\exception.py", line 34, in inner
    response = get_response(request)
  File "C:\Users\Administrator\venv\lib\site-packages\django\core\handlers\base.py", line 126, in _get_response
    response = self.process_exception_by_middleware(e, request)
  File "C:\Users\Administrator\venv\lib\site-packages\django\core\handlers\base.py", line 124, in _get_response
    response = wrapped_callback(request, *callback_args, **callback_kwargs)
  File "D:\项目汇总\kanban\basics\views\plan.py", line 40, in getAllPlans
    if list(assys)[0][0]:
IndexError: list index out of range
2018-09-25 08:56:11,180 - Internal Server Error: /getAllPlans
Traceback (most recent call last):
  File "C:\Users\Administrator\venv\lib\site-packages\django\core\handlers\exception.py", line 34, in inner
    response = get_response(request)
  File "C:\Users\Administrator\venv\lib\site-packages\django\core\handlers\base.py", line 126, in _get_response
    response = self.process_exception_by_middleware(e, request)
  File "C:\Users\Administrator\venv\lib\site-packages\django\core\handlers\base.py", line 124, in _get_response
    response = wrapped_callback(request, *callback_args, **callback_kwargs)
  File "D:\项目汇总\kanban\basics\views\plan.py", line 40, in getAllPlans
    if list(assys)[0][0]:
IndexError: list index out of range
2018-09-25 08:59:04,604 - Internal Server Error: /getAllPlans
Traceback (most recent call last):
  File "C:\Users\Administrator\venv\lib\site-packages\django\core\handlers\exception.py", line 34, in inner
    response = get_response(request)
  File "C:\Users\Administrator\venv\lib\site-packages\django\core\handlers\base.py", line 126, in _get_response
    response = self.process_exception_by_middleware(e, request)
  File "C:\Users\Administrator\venv\lib\site-packages\django\core\handlers\base.py", line 124, in _get_response
    response = wrapped_callback(request, *callback_args, **callback_kwargs)
  File "D:\项目汇总\kanban\basics\views\plan.py", line 40, in getAllPlans
    if list(assys)[0][0]:
IndexError: list index out of range
2018-09-27 13:15:30,344 - Not Found: /img/favicon.png
2018-09-27 14:51:47,433 - Not Found: /img/favicon.png
2018-09-25 14:55:49,764 - Internal Server Error: /getAllPlans
Traceback (most recent call last):
  File "C:\Users\Administrator\venv\lib\site-packages\django\core\handlers\exception.py", line 34, in inner
    response = get_response(request)
  File "C:\Users\Administrator\venv\lib\site-packages\django\core\handlers\base.py", line 126, in _get_response
    response = self.process_exception_by_middleware(e, request)
  File "C:\Users\Administrator\venv\lib\site-packages\django\core\handlers\base.py", line 124, in _get_response
    response = wrapped_callback(request, *callback_args, **callback_kwargs)
  File "D:\项目汇总\kanban\basics\views\plan.py", line 40, in getAllPlans
    if list(assys)[0][0]:
IndexError: list index out of range
2018-09-25 14:55:50,011 - Internal Server Error: /initData
Traceback (most recent call last):
  File "C:\Users\Administrator\venv\lib\site-packages\django\db\backends\utils.py", line 83, in _execute
    return self.cursor.execute(sql)
psycopg2.ProgrammingError: syntax error at end of input
LINE 1: SELECT see_assys FROM m_user WHERE id=
                                              ^


The above exception was the direct cause of the following exception:

Traceback (most recent call last):
  File "C:\Users\Administrator\venv\lib\site-packages\django\core\handlers\exception.py", line 34, in inner
    response = get_response(request)
  File "C:\Users\Administrator\venv\lib\site-packages\django\core\handlers\base.py", line 126, in _get_response
    response = self.process_exception_by_middleware(e, request)
  File "C:\Users\Administrator\venv\lib\site-packages\django\core\handlers\base.py", line 124, in _get_response
    response = wrapped_callback(request, *callback_args, **callback_kwargs)
  File "D:\项目汇总\kanban\RtMonSys\views\view_homePage.py", line 19, in initData
    result = model_homePage.initData(request)
  File "D:\项目汇总\kanban\RtMonSys\models\model_homePage.py", line 88, in initData
    cur.execute(SQL_1)
  File "C:\Users\Administrator\venv\lib\site-packages\django\db\backends\utils.py", line 100, in execute
    return super().execute(sql, params)
  File "C:\Users\Administrator\venv\lib\site-packages\django\db\backends\utils.py", line 68, in execute
    return self._execute_with_wrappers(sql, params, many=False, executor=self._execute)
  File "C:\Users\Administrator\venv\lib\site-packages\django\db\backends\utils.py", line 77, in _execute_with_wrappers
    return executor(sql, params, many, context)
  File "C:\Users\Administrator\venv\lib\site-packages\django\db\backends\utils.py", line 85, in _execute
    return self.cursor.execute(sql, params)
  File "C:\Users\Administrator\venv\lib\site-packages\django\db\utils.py", line 89, in __exit__
    raise dj_exc_value.with_traceback(traceback) from exc_value
  File "C:\Users\Administrator\venv\lib\site-packages\django\db\backends\utils.py", line 83, in _execute
    return self.cursor.execute(sql)
django.db.utils.ProgrammingError: syntax error at end of input
LINE 1: SELECT see_assys FROM m_user WHERE id=
                                              ^

2018-09-25 14:55:50,288 - Not Found: /img/favicon.png
2018-09-28 08:30:24,347 - Internal Server Error: /initData
Traceback (most recent call last):
  File "C:\Users\Administrator\venv\lib\site-packages\django\db\backends\utils.py", line 85, in _execute
    return self.cursor.execute(sql, params)
psycopg2.ProgrammingError: relation "t_history" does not exist
LINE 5:             t_history 
                    ^


The above exception was the direct cause of the following exception:

Traceback (most recent call last):
  File "C:\Users\Administrator\venv\lib\site-packages\django\core\handlers\exception.py", line 34, in inner
    response = get_response(request)
  File "C:\Users\Administrator\venv\lib\site-packages\django\core\handlers\base.py", line 126, in _get_response
    response = self.process_exception_by_middleware(e, request)
  File "C:\Users\Administrator\venv\lib\site-packages\django\core\handlers\base.py", line 124, in _get_response
    response = wrapped_callback(request, *callback_args, **callback_kwargs)
  File "D:\项目汇总\kanban\RtMonSys\views\view_homePage.py", line 19, in initData
    result = model_homePage.initData(request)
  File "D:\项目汇总\kanban\RtMonSys\models\model_homePage.py", line 148, in initData
    cur.execute(SQL_3, (datestr, datestr, now_time))  # 查出各产线今天有没有数据
  File "C:\Users\Administrator\venv\lib\site-packages\django\db\backends\utils.py", line 100, in execute
    return super().execute(sql, params)
  File "C:\Users\Administrator\venv\lib\site-packages\django\db\backends\utils.py", line 68, in execute
    return self._execute_with_wrappers(sql, params, many=False, executor=self._execute)
  File "C:\Users\Administrator\venv\lib\site-packages\django\db\backends\utils.py", line 77, in _execute_with_wrappers
    return executor(sql, params, many, context)
  File "C:\Users\Administrator\venv\lib\site-packages\django\db\backends\utils.py", line 85, in _execute
    return self.cursor.execute(sql, params)
  File "C:\Users\Administrator\venv\lib\site-packages\django\db\utils.py", line 89, in __exit__
    raise dj_exc_value.with_traceback(traceback) from exc_value
  File "C:\Users\Administrator\venv\lib\site-packages\django\db\backends\utils.py", line 85, in _execute
    return self.cursor.execute(sql, params)
django.db.utils.ProgrammingError: relation "t_history" does not exist
LINE 5:             t_history 
                    ^

2018-09-28 08:30:34,788 - Internal Server Error: /initData
Traceback (most recent call last):
  File "C:\Users\Administrator\venv\lib\site-packages\django\db\backends\utils.py", line 85, in _execute
    return self.cursor.execute(sql, params)
psycopg2.ProgrammingError: relation "t_history" does not exist
LINE 5:             t_history 
                    ^


The above exception was the direct cause of the following exception:

Traceback (most recent call last):
  File "C:\Users\Administrator\venv\lib\site-packages\django\core\handlers\exception.py", line 34, in inner
    response = get_response(request)
  File "C:\Users\Administrator\venv\lib\site-packages\django\core\handlers\base.py", line 126, in _get_response
    response = self.process_exception_by_middleware(e, request)
  File "C:\Users\Administrator\venv\lib\site-packages\django\core\handlers\base.py", line 124, in _get_response
    response = wrapped_callback(request, *callback_args, **callback_kwargs)
  File "D:\项目汇总\kanban\RtMonSys\views\view_homePage.py", line 19, in initData
    result = model_homePage.initData(request)
  File "D:\项目汇总\kanban\RtMonSys\models\model_homePage.py", line 148, in initData
    cur.execute(SQL_3, (datestr, datestr, now_time))  # 查出各产线今天有没有数据
  File "C:\Users\Administrator\venv\lib\site-packages\django\db\backends\utils.py", line 100, in execute
    return super().execute(sql, params)
  File "C:\Users\Administrator\venv\lib\site-packages\django\db\backends\utils.py", line 68, in execute
    return self._execute_with_wrappers(sql, params, many=False, executor=self._execute)
  File "C:\Users\Administrator\venv\lib\site-packages\django\db\backends\utils.py", line 77, in _execute_with_wrappers
    return executor(sql, params, many, context)
  File "C:\Users\Administrator\venv\lib\site-packages\django\db\backends\utils.py", line 85, in _execute
    return self.cursor.execute(sql, params)
  File "C:\Users\Administrator\venv\lib\site-packages\django\db\utils.py", line 89, in __exit__
    raise dj_exc_value.with_traceback(traceback) from exc_value
  File "C:\Users\Administrator\venv\lib\site-packages\django\db\backends\utils.py", line 85, in _execute
    return self.cursor.execute(sql, params)
django.db.utils.ProgrammingError: relation "t_history" does not exist
LINE 5:             t_history 
                    ^

2018-09-28 08:30:44,780 - Internal Server Error: /initData
Traceback (most recent call last):
  File "C:\Users\Administrator\venv\lib\site-packages\django\db\backends\utils.py", line 85, in _execute
    return self.cursor.execute(sql, params)
psycopg2.ProgrammingError: relation "t_history" does not exist
LINE 5:             t_history 
                    ^


The above exception was the direct cause of the following exception:

Traceback (most recent call last):
  File "C:\Users\Administrator\venv\lib\site-packages\django\core\handlers\exception.py", line 34, in inner
    response = get_response(request)
  File "C:\Users\Administrator\venv\lib\site-packages\django\core\handlers\base.py", line 126, in _get_response
    response = self.process_exception_by_middleware(e, request)
  File "C:\Users\Administrator\venv\lib\site-packages\django\core\handlers\base.py", line 124, in _get_response
    response = wrapped_callback(request, *callback_args, **callback_kwargs)
  File "D:\项目汇总\kanban\RtMonSys\views\view_homePage.py", line 19, in initData
    result = model_homePage.initData(request)
  File "D:\项目汇总\kanban\RtMonSys\models\model_homePage.py", line 148, in initData
    cur.execute(SQL_3, (datestr, datestr, now_time))  # 查出各产线今天有没有数据
  File "C:\Users\Administrator\venv\lib\site-packages\django\db\backends\utils.py", line 100, in execute
    return super().execute(sql, params)
  File "C:\Users\Administrator\venv\lib\site-packages\django\db\backends\utils.py", line 68, in execute
    return self._execute_with_wrappers(sql, params, many=False, executor=self._execute)
  File "C:\Users\Administrator\venv\lib\site-packages\django\db\backends\utils.py", line 77, in _execute_with_wrappers
    return executor(sql, params, many, context)
  File "C:\Users\Administrator\venv\lib\site-packages\django\db\backends\utils.py", line 85, in _execute
    return self.cursor.execute(sql, params)
  File "C:\Users\Administrator\venv\lib\site-packages\django\db\utils.py", line 89, in __exit__
    raise dj_exc_value.with_traceback(traceback) from exc_value
  File "C:\Users\Administrator\venv\lib\site-packages\django\db\backends\utils.py", line 85, in _execute
    return self.cursor.execute(sql, params)
django.db.utils.ProgrammingError: relation "t_history" does not exist
LINE 5:             t_history 
                    ^

2018-09-28 08:30:54,777 - Internal Server Error: /initData
Traceback (most recent call last):
  File "C:\Users\Administrator\venv\lib\site-packages\django\db\backends\utils.py", line 85, in _execute
    return self.cursor.execute(sql, params)
psycopg2.ProgrammingError: relation "t_history" does not exist
LINE 5:             t_history 
                    ^


The above exception was the direct cause of the following exception:

Traceback (most recent call last):
  File "C:\Users\Administrator\venv\lib\site-packages\django\core\handlers\exception.py", line 34, in inner
    response = get_response(request)
  File "C:\Users\Administrator\venv\lib\site-packages\django\core\handlers\base.py", line 126, in _get_response
    response = self.process_exception_by_middleware(e, request)
  File "C:\Users\Administrator\venv\lib\site-packages\django\core\handlers\base.py", line 124, in _get_response
    response = wrapped_callback(request, *callback_args, **callback_kwargs)
  File "D:\项目汇总\kanban\RtMonSys\views\view_homePage.py", line 19, in initData
    result = model_homePage.initData(request)
  File "D:\项目汇总\kanban\RtMonSys\models\model_homePage.py", line 148, in initData
    cur.execute(SQL_3, (datestr, datestr, now_time))  # 查出各产线今天有没有数据
  File "C:\Users\Administrator\venv\lib\site-packages\django\db\backends\utils.py", line 100, in execute
    return super().execute(sql, params)
  File "C:\Users\Administrator\venv\lib\site-packages\django\db\backends\utils.py", line 68, in execute
    return self._execute_with_wrappers(sql, params, many=False, executor=self._execute)
  File "C:\Users\Administrator\venv\lib\site-packages\django\db\backends\utils.py", line 77, in _execute_with_wrappers
    return executor(sql, params, many, context)
  File "C:\Users\Administrator\venv\lib\site-packages\django\db\backends\utils.py", line 85, in _execute
    return self.cursor.execute(sql, params)
  File "C:\Users\Administrator\venv\lib\site-packages\django\db\utils.py", line 89, in __exit__
    raise dj_exc_value.with_traceback(traceback) from exc_value
  File "C:\Users\Administrator\venv\lib\site-packages\django\db\backends\utils.py", line 85, in _execute
    return self.cursor.execute(sql, params)
django.db.utils.ProgrammingError: relation "t_history" does not exist
LINE 5:             t_history 
                    ^

2018-09-28 08:31:04,783 - Internal Server Error: /initData
Traceback (most recent call last):
  File "C:\Users\Administrator\venv\lib\site-packages\django\db\backends\utils.py", line 85, in _execute
    return self.cursor.execute(sql, params)
psycopg2.ProgrammingError: relation "t_history" does not exist
LINE 5:             t_history 
                    ^


The above exception was the direct cause of the following exception:

Traceback (most recent call last):
  File "C:\Users\Administrator\venv\lib\site-packages\django\core\handlers\exception.py", line 34, in inner
    response = get_response(request)
  File "C:\Users\Administrator\venv\lib\site-packages\django\core\handlers\base.py", line 126, in _get_response
    response = self.process_exception_by_middleware(e, request)
  File "C:\Users\Administrator\venv\lib\site-packages\django\core\handlers\base.py", line 124, in _get_response
    response = wrapped_callback(request, *callback_args, **callback_kwargs)
  File "D:\项目汇总\kanban\RtMonSys\views\view_homePage.py", line 19, in initData
    result = model_homePage.initData(request)
  File "D:\项目汇总\kanban\RtMonSys\models\model_homePage.py", line 148, in initData
    cur.execute(SQL_3, (datestr, datestr, now_time))  # 查出各产线今天有没有数据
  File "C:\Users\Administrator\venv\lib\site-packages\django\db\backends\utils.py", line 100, in execute
    return super().execute(sql, params)
  File "C:\Users\Administrator\venv\lib\site-packages\django\db\backends\utils.py", line 68, in execute
    return self._execute_with_wrappers(sql, params, many=False, executor=self._execute)
  File "C:\Users\Administrator\venv\lib\site-packages\django\db\backends\utils.py", line 77, in _execute_with_wrappers
    return executor(sql, params, many, context)
  File "C:\Users\Administrator\venv\lib\site-packages\django\db\backends\utils.py", line 85, in _execute
    return self.cursor.execute(sql, params)
  File "C:\Users\Administrator\venv\lib\site-packages\django\db\utils.py", line 89, in __exit__
    raise dj_exc_value.with_traceback(traceback) from exc_value
  File "C:\Users\Administrator\venv\lib\site-packages\django\db\backends\utils.py", line 85, in _execute
    return self.cursor.execute(sql, params)
django.db.utils.ProgrammingError: relation "t_history" does not exist
LINE 5:             t_history 
                    ^

2018-09-28 08:31:14,776 - Internal Server Error: /initData
Traceback (most recent call last):
  File "C:\Users\Administrator\venv\lib\site-packages\django\db\backends\utils.py", line 85, in _execute
    return self.cursor.execute(sql, params)
psycopg2.ProgrammingError: relation "t_history" does not exist
LINE 5:             t_history 
                    ^


The above exception was the direct cause of the following exception:

Traceback (most recent call last):
  File "C:\Users\Administrator\venv\lib\site-packages\django\core\handlers\exception.py", line 34, in inner
    response = get_response(request)
  File "C:\Users\Administrator\venv\lib\site-packages\django\core\handlers\base.py", line 126, in _get_response
    response = self.process_exception_by_middleware(e, request)
  File "C:\Users\Administrator\venv\lib\site-packages\django\core\handlers\base.py", line 124, in _get_response
    response = wrapped_callback(request, *callback_args, **callback_kwargs)
  File "D:\项目汇总\kanban\RtMonSys\views\view_homePage.py", line 19, in initData
    result = model_homePage.initData(request)
  File "D:\项目汇总\kanban\RtMonSys\models\model_homePage.py", line 148, in initData
    cur.execute(SQL_3, (datestr, datestr, now_time))  # 查出各产线今天有没有数据
  File "C:\Users\Administrator\venv\lib\site-packages\django\db\backends\utils.py", line 100, in execute
    return super().execute(sql, params)
  File "C:\Users\Administrator\venv\lib\site-packages\django\db\backends\utils.py", line 68, in execute
    return self._execute_with_wrappers(sql, params, many=False, executor=self._execute)
  File "C:\Users\Administrator\venv\lib\site-packages\django\db\backends\utils.py", line 77, in _execute_with_wrappers
    return executor(sql, params, many, context)
  File "C:\Users\Administrator\venv\lib\site-packages\django\db\backends\utils.py", line 85, in _execute
    return self.cursor.execute(sql, params)
  File "C:\Users\Administrator\venv\lib\site-packages\django\db\utils.py", line 89, in __exit__
    raise dj_exc_value.with_traceback(traceback) from exc_value
  File "C:\Users\Administrator\venv\lib\site-packages\django\db\backends\utils.py", line 85, in _execute
    return self.cursor.execute(sql, params)
django.db.utils.ProgrammingError: relation "t_history" does not exist
LINE 5:             t_history 
                    ^

2018-09-28 08:31:24,781 - Internal Server Error: /initData
Traceback (most recent call last):
  File "C:\Users\Administrator\venv\lib\site-packages\django\db\backends\utils.py", line 85, in _execute
    return self.cursor.execute(sql, params)
psycopg2.ProgrammingError: relation "t_history" does not exist
LINE 5:             t_history 
                    ^


The above exception was the direct cause of the following exception:

Traceback (most recent call last):
  File "C:\Users\Administrator\venv\lib\site-packages\django\core\handlers\exception.py", line 34, in inner
    response = get_response(request)
  File "C:\Users\Administrator\venv\lib\site-packages\django\core\handlers\base.py", line 126, in _get_response
    response = self.process_exception_by_middleware(e, request)
  File "C:\Users\Administrator\venv\lib\site-packages\django\core\handlers\base.py", line 124, in _get_response
    response = wrapped_callback(request, *callback_args, **callback_kwargs)
  File "D:\项目汇总\kanban\RtMonSys\views\view_homePage.py", line 19, in initData
    result = model_homePage.initData(request)
  File "D:\项目汇总\kanban\RtMonSys\models\model_homePage.py", line 148, in initData
    cur.execute(SQL_3, (datestr, datestr, now_time))  # 查出各产线今天有没有数据
  File "C:\Users\Administrator\venv\lib\site-packages\django\db\backends\utils.py", line 100, in execute
    return super().execute(sql, params)
  File "C:\Users\Administrator\venv\lib\site-packages\django\db\backends\utils.py", line 68, in execute
    return self._execute_with_wrappers(sql, params, many=False, executor=self._execute)
  File "C:\Users\Administrator\venv\lib\site-packages\django\db\backends\utils.py", line 77, in _execute_with_wrappers
    return executor(sql, params, many, context)
  File "C:\Users\Administrator\venv\lib\site-packages\django\db\backends\utils.py", line 85, in _execute
    return self.cursor.execute(sql, params)
  File "C:\Users\Administrator\venv\lib\site-packages\django\db\utils.py", line 89, in __exit__
    raise dj_exc_value.with_traceback(traceback) from exc_value
  File "C:\Users\Administrator\venv\lib\site-packages\django\db\backends\utils.py", line 85, in _execute
    return self.cursor.execute(sql, params)
django.db.utils.ProgrammingError: relation "t_history" does not exist
LINE 5:             t_history 
                    ^

2018-09-28 08:31:34,781 - Internal Server Error: /initData
Traceback (most recent call last):
  File "C:\Users\Administrator\venv\lib\site-packages\django\db\backends\utils.py", line 85, in _execute
    return self.cursor.execute(sql, params)
psycopg2.ProgrammingError: relation "t_history" does not exist
LINE 5:             t_history 
                    ^


The above exception was the direct cause of the following exception:

Traceback (most recent call last):
  File "C:\Users\Administrator\venv\lib\site-packages\django\core\handlers\exception.py", line 34, in inner
    response = get_response(request)
  File "C:\Users\Administrator\venv\lib\site-packages\django\core\handlers\base.py", line 126, in _get_response
    response = self.process_exception_by_middleware(e, request)
  File "C:\Users\Administrator\venv\lib\site-packages\django\core\handlers\base.py", line 124, in _get_response
    response = wrapped_callback(request, *callback_args, **callback_kwargs)
  File "D:\项目汇总\kanban\RtMonSys\views\view_homePage.py", line 19, in initData
    result = model_homePage.initData(request)
  File "D:\项目汇总\kanban\RtMonSys\models\model_homePage.py", line 148, in initData
    cur.execute(SQL_3, (datestr, datestr, now_time))  # 查出各产线今天有没有数据
  File "C:\Users\Administrator\venv\lib\site-packages\django\db\backends\utils.py", line 100, in execute
    return super().execute(sql, params)
  File "C:\Users\Administrator\venv\lib\site-packages\django\db\backends\utils.py", line 68, in execute
    return self._execute_with_wrappers(sql, params, many=False, executor=self._execute)
  File "C:\Users\Administrator\venv\lib\site-packages\django\db\backends\utils.py", line 77, in _execute_with_wrappers
    return executor(sql, params, many, context)
  File "C:\Users\Administrator\venv\lib\site-packages\django\db\backends\utils.py", line 85, in _execute
    return self.cursor.execute(sql, params)
  File "C:\Users\Administrator\venv\lib\site-packages\django\db\utils.py", line 89, in __exit__
    raise dj_exc_value.with_traceback(traceback) from exc_value
  File "C:\Users\Administrator\venv\lib\site-packages\django\db\backends\utils.py", line 85, in _execute
    return self.cursor.execute(sql, params)
django.db.utils.ProgrammingError: relation "t_history" does not exist
LINE 5:             t_history 
                    ^

2018-09-28 08:31:44,783 - Internal Server Error: /initData
Traceback (most recent call last):
  File "C:\Users\Administrator\venv\lib\site-packages\django\db\backends\utils.py", line 85, in _execute
    return self.cursor.execute(sql, params)
psycopg2.ProgrammingError: relation "t_history" does not exist
LINE 5:             t_history 
                    ^


The above exception was the direct cause of the following exception:

Traceback (most recent call last):
  File "C:\Users\Administrator\venv\lib\site-packages\django\core\handlers\exception.py", line 34, in inner
    response = get_response(request)
  File "C:\Users\Administrator\venv\lib\site-packages\django\core\handlers\base.py", line 126, in _get_response
    response = self.process_exception_by_middleware(e, request)
  File "C:\Users\Administrator\venv\lib\site-packages\django\core\handlers\base.py", line 124, in _get_response
    response = wrapped_callback(request, *callback_args, **callback_kwargs)
  File "D:\项目汇总\kanban\RtMonSys\views\view_homePage.py", line 19, in initData
    result = model_homePage.initData(request)
  File "D:\项目汇总\kanban\RtMonSys\models\model_homePage.py", line 148, in initData
    cur.execute(SQL_3, (datestr, datestr, now_time))  # 查出各产线今天有没有数据
  File "C:\Users\Administrator\venv\lib\site-packages\django\db\backends\utils.py", line 100, in execute
    return super().execute(sql, params)
  File "C:\Users\Administrator\venv\lib\site-packages\django\db\backends\utils.py", line 68, in execute
    return self._execute_with_wrappers(sql, params, many=False, executor=self._execute)
  File "C:\Users\Administrator\venv\lib\site-packages\django\db\backends\utils.py", line 77, in _execute_with_wrappers
    return executor(sql, params, many, context)
  File "C:\Users\Administrator\venv\lib\site-packages\django\db\backends\utils.py", line 85, in _execute
    return self.cursor.execute(sql, params)
  File "C:\Users\Administrator\venv\lib\site-packages\django\db\utils.py", line 89, in __exit__
    raise dj_exc_value.with_traceback(traceback) from exc_value
  File "C:\Users\Administrator\venv\lib\site-packages\django\db\backends\utils.py", line 85, in _execute
    return self.cursor.execute(sql, params)
django.db.utils.ProgrammingError: relation "t_history" does not exist
LINE 5:             t_history 
                    ^

2018-09-28 08:31:54,791 - Internal Server Error: /initData
Traceback (most recent call last):
  File "C:\Users\Administrator\venv\lib\site-packages\django\db\backends\utils.py", line 85, in _execute
    return self.cursor.execute(sql, params)
psycopg2.ProgrammingError: relation "t_history" does not exist
LINE 5:             t_history 
                    ^


The above exception was the direct cause of the following exception:

Traceback (most recent call last):
  File "C:\Users\Administrator\venv\lib\site-packages\django\core\handlers\exception.py", line 34, in inner
    response = get_response(request)
  File "C:\Users\Administrator\venv\lib\site-packages\django\core\handlers\base.py", line 126, in _get_response
    response = self.process_exception_by_middleware(e, request)
  File "C:\Users\Administrator\venv\lib\site-packages\django\core\handlers\base.py", line 124, in _get_response
    response = wrapped_callback(request, *callback_args, **callback_kwargs)
  File "D:\项目汇总\kanban\RtMonSys\views\view_homePage.py", line 19, in initData
    result = model_homePage.initData(request)
  File "D:\项目汇总\kanban\RtMonSys\models\model_homePage.py", line 148, in initData
    cur.execute(SQL_3, (datestr, datestr, now_time))  # 查出各产线今天有没有数据
  File "C:\Users\Administrator\venv\lib\site-packages\django\db\backends\utils.py", line 100, in execute
    return super().execute(sql, params)
  File "C:\Users\Administrator\venv\lib\site-packages\django\db\backends\utils.py", line 68, in execute
    return self._execute_with_wrappers(sql, params, many=False, executor=self._execute)
  File "C:\Users\Administrator\venv\lib\site-packages\django\db\backends\utils.py", line 77, in _execute_with_wrappers
    return executor(sql, params, many, context)
  File "C:\Users\Administrator\venv\lib\site-packages\django\db\backends\utils.py", line 85, in _execute
    return self.cursor.execute(sql, params)
  File "C:\Users\Administrator\venv\lib\site-packages\django\db\utils.py", line 89, in __exit__
    raise dj_exc_value.with_traceback(traceback) from exc_value
  File "C:\Users\Administrator\venv\lib\site-packages\django\db\backends\utils.py", line 85, in _execute
    return self.cursor.execute(sql, params)
django.db.utils.ProgrammingError: relation "t_history" does not exist
LINE 5:             t_history 
                    ^

2018-09-28 08:32:04,780 - Internal Server Error: /initData
Traceback (most recent call last):
  File "C:\Users\Administrator\venv\lib\site-packages\django\db\backends\utils.py", line 85, in _execute
    return self.cursor.execute(sql, params)
psycopg2.ProgrammingError: relation "t_history" does not exist
LINE 5:             t_history 
                    ^


The above exception was the direct cause of the following exception:

Traceback (most recent call last):
  File "C:\Users\Administrator\venv\lib\site-packages\django\core\handlers\exception.py", line 34, in inner
    response = get_response(request)
  File "C:\Users\Administrator\venv\lib\site-packages\django\core\handlers\base.py", line 126, in _get_response
    response = self.process_exception_by_middleware(e, request)
  File "C:\Users\Administrator\venv\lib\site-packages\django\core\handlers\base.py", line 124, in _get_response
    response = wrapped_callback(request, *callback_args, **callback_kwargs)
  File "D:\项目汇总\kanban\RtMonSys\views\view_homePage.py", line 19, in initData
    result = model_homePage.initData(request)
  File "D:\项目汇总\kanban\RtMonSys\models\model_homePage.py", line 148, in initData
    cur.execute(SQL_3, (datestr, datestr, now_time))  # 查出各产线今天有没有数据
  File "C:\Users\Administrator\venv\lib\site-packages\django\db\backends\utils.py", line 100, in execute
    return super().execute(sql, params)
  File "C:\Users\Administrator\venv\lib\site-packages\django\db\backends\utils.py", line 68, in execute
    return self._execute_with_wrappers(sql, params, many=False, executor=self._execute)
  File "C:\Users\Administrator\venv\lib\site-packages\django\db\backends\utils.py", line 77, in _execute_with_wrappers
    return executor(sql, params, many, context)
  File "C:\Users\Administrator\venv\lib\site-packages\django\db\backends\utils.py", line 85, in _execute
    return self.cursor.execute(sql, params)
  File "C:\Users\Administrator\venv\lib\site-packages\django\db\utils.py", line 89, in __exit__
    raise dj_exc_value.with_traceback(traceback) from exc_value
  File "C:\Users\Administrator\venv\lib\site-packages\django\db\backends\utils.py", line 85, in _execute
    return self.cursor.execute(sql, params)
django.db.utils.ProgrammingError: relation "t_history" does not exist
LINE 5:             t_history 
                    ^

2018-09-28 09:21:57,361 - Not Found: /img/favicon.png
2018-10-09 10:06:21,396 - Not Found: /img/favicon.png
2018-10-09 14:49:48,839 - Not Found: /img/favicon.png
2018-10-09 16:24:02,448 - Not Found: /img/favicon.png
2018-10-09 16:55:31,057 - Not Found: /img/favicon.png
2018-08-05 13:23:17,448 - Internal Server Error: /initData
Traceback (most recent call last):
  File "C:\Users\Administrator\venv\lib\site-packages\django\db\backends\utils.py", line 83, in _execute
    return self.cursor.execute(sql)
psycopg2.ProgrammingError: syntax error at end of input
LINE 1: SELECT see_assys FROM m_user WHERE id=
                                              ^


The above exception was the direct cause of the following exception:

Traceback (most recent call last):
  File "C:\Users\Administrator\venv\lib\site-packages\django\core\handlers\exception.py", line 34, in inner
    response = get_response(request)
  File "C:\Users\Administrator\venv\lib\site-packages\django\core\handlers\base.py", line 126, in _get_response
    response = self.process_exception_by_middleware(e, request)
  File "C:\Users\Administrator\venv\lib\site-packages\django\core\handlers\base.py", line 124, in _get_response
    response = wrapped_callback(request, *callback_args, **callback_kwargs)
  File "D:\项目汇总\kanban\RtMonSys\views\view_homePage.py", line 19, in initData
    result = model_homePage.initData(request)
  File "D:\项目汇总\kanban\RtMonSys\models\model_homePage.py", line 88, in initData
    cur.execute(SQL_1)
  File "C:\Users\Administrator\venv\lib\site-packages\django\db\backends\utils.py", line 100, in execute
    return super().execute(sql, params)
  File "C:\Users\Administrator\venv\lib\site-packages\django\db\backends\utils.py", line 68, in execute
    return self._execute_with_wrappers(sql, params, many=False, executor=self._execute)
  File "C:\Users\Administrator\venv\lib\site-packages\django\db\backends\utils.py", line 77, in _execute_with_wrappers
    return executor(sql, params, many, context)
  File "C:\Users\Administrator\venv\lib\site-packages\django\db\backends\utils.py", line 85, in _execute
    return self.cursor.execute(sql, params)
  File "C:\Users\Administrator\venv\lib\site-packages\django\db\utils.py", line 89, in __exit__
    raise dj_exc_value.with_traceback(traceback) from exc_value
  File "C:\Users\Administrator\venv\lib\site-packages\django\db\backends\utils.py", line 83, in _execute
    return self.cursor.execute(sql)
django.db.utils.ProgrammingError: syntax error at end of input
LINE 1: SELECT see_assys FROM m_user WHERE id=
                                              ^

2018-11-09 16:16:54,649 - Internal Server Error: /
Traceback (most recent call last):
  File "C:\Users\Administrator\venv\lib\site-packages\django\core\handlers\exception.py", line 34, in inner
    response = get_response(request)
  File "C:\Users\Administrator\venv\lib\site-packages\django\core\handlers\base.py", line 126, in _get_response
    response = self.process_exception_by_middleware(e, request)
  File "C:\Users\Administrator\venv\lib\site-packages\django\core\handlers\base.py", line 124, in _get_response
    response = wrapped_callback(request, *callback_args, **callback_kwargs)
  File "D:\项目汇总\仓库管理\RtMonSys\views\view_config.py", line 11, in go_config
    return render(request, 'config/index.html')
  File "C:\Users\Administrator\venv\lib\site-packages\django\shortcuts.py", line 36, in render
    content = loader.render_to_string(template_name, context, request, using=using)
  File "C:\Users\Administrator\venv\lib\site-packages\django\template\loader.py", line 61, in render_to_string
    template = get_template(template_name, using=using)
  File "C:\Users\Administrator\venv\lib\site-packages\django\template\loader.py", line 19, in get_template
    raise TemplateDoesNotExist(template_name, chain=chain)
django.template.exceptions.TemplateDoesNotExist: config/index.html
2018-11-09 16:17:36,153 - Not Found: /go_homePage
2018-11-09 16:37:06,788 - Not Found: /go_config
2018-11-09 16:51:12,231 - Not Found: /dist/img/user2-160x160.jpg
2018-11-09 16:56:42,093 - Not Found: /index.html
2018-11-09 16:57:26,888 - Not Found: /index.html
2018-11-12 10:00:16,394 - Internal Server Error: /
Traceback (most recent call last):
  File "C:\Users\Administrator\venv\lib\site-packages\django\template\backends\django.py", line 61, in render
    return self.template.render(context)
  File "C:\Users\Administrator\venv\lib\site-packages\django\template\base.py", line 171, in render
    return self._render(context)
  File "C:\Users\Administrator\venv\lib\site-packages\django\template\base.py", line 163, in _render
    return self.nodelist.render(context)
  File "C:\Users\Administrator\venv\lib\site-packages\django\template\base.py", line 937, in render
    bit = node.render_annotated(context)
  File "C:\Users\Administrator\venv\lib\site-packages\django\template\base.py", line 904, in render_annotated
    return self.render(context)
  File "C:\Users\Administrator\venv\lib\site-packages\django\template\loader_tags.py", line 150, in render
    return compiled_parent._render(context)
  File "C:\Users\Administrator\venv\lib\site-packages\django\template\base.py", line 163, in _render
    return self.nodelist.render(context)
  File "C:\Users\Administrator\venv\lib\site-packages\django\template\base.py", line 937, in render
    bit = node.render_annotated(context)
  File "C:\Users\Administrator\venv\lib\site-packages\django\template\base.py", line 904, in render_annotated
    return self.render(context)
  File "C:\Users\Administrator\venv\lib\site-packages\django\template\loader_tags.py", line 62, in render
    result = block.nodelist.render(context)
  File "C:\Users\Administrator\venv\lib\site-packages\django\template\base.py", line 937, in render
    bit = node.render_annotated(context)
  File "C:\Users\Administrator\venv\lib\site-packages\django\template\base.py", line 904, in render_annotated
    return self.render(context)
  File "C:\Users\Administrator\venv\lib\site-packages\django\template\loader_tags.py", line 188, in render
    return template.render(context)
  File "C:\Users\Administrator\venv\lib\site-packages\django\template\base.py", line 173, in render
    return self._render(context)
  File "C:\Users\Administrator\venv\lib\site-packages\django\template\base.py", line 163, in _render
    return self.nodelist.render(context)
  File "C:\Users\Administrator\venv\lib\site-packages\django\template\base.py", line 937, in render
    bit = node.render_annotated(context)
  File "C:\Users\Administrator\venv\lib\site-packages\django\template\base.py", line 904, in render_annotated
    return self.render(context)
  File "C:\Users\Administrator\venv\lib\site-packages\django\template\loader_tags.py", line 176, in render
    template = context.template.engine.get_template(template_name)
  File "C:\Users\Administrator\venv\lib\site-packages\django\template\engine.py", line 144, in get_template
    template, origin = self.find_template(template_name)
  File "C:\Users\Administrator\venv\lib\site-packages\django\template\engine.py", line 130, in find_template
    raise TemplateDoesNotExist(name, tried=tried)
django.template.exceptions.TemplateDoesNotExist: public/page.html

The above exception was the direct cause of the following exception:

Traceback (most recent call last):
  File "C:\Users\Administrator\venv\lib\site-packages\django\core\handlers\exception.py", line 34, in inner
    response = get_response(request)
  File "C:\Users\Administrator\venv\lib\site-packages\django\core\handlers\base.py", line 126, in _get_response
    response = self.process_exception_by_middleware(e, request)
  File "C:\Users\Administrator\venv\lib\site-packages\django\core\handlers\base.py", line 124, in _get_response
    response = wrapped_callback(request, *callback_args, **callback_kwargs)
  File "D:\项目汇总\仓库管理\trank_\RtMonSys\views\view_store_in.py", line 12, in go_store_in
    return render(request, 'base/store/store_in/index.html')
  File "C:\Users\Administrator\venv\lib\site-packages\django\shortcuts.py", line 36, in render
    content = loader.render_to_string(template_name, context, request, using=using)
  File "C:\Users\Administrator\venv\lib\site-packages\django\template\loader.py", line 62, in render_to_string
    return template.render(context, request)
  File "C:\Users\Administrator\venv\lib\site-packages\django\template\backends\django.py", line 63, in render
    reraise(exc, self.backend)
  File "C:\Users\Administrator\venv\lib\site-packages\django\template\backends\django.py", line 84, in reraise
    raise new from exc
django.template.exceptions.TemplateDoesNotExist: public/page.html
2018-11-12 13:54:20,844 - Not Found: /index.html
2018-11-12 13:54:56,121 - Not Found: /index.html
2018-11-12 13:54:58,539 - Not Found: /index.html
2018-11-12 13:54:59,057 - Not Found: /index.html
2018-11-12 13:54:59,282 - Not Found: /index.html
2018-11-12 13:54:59,489 - Not Found: /index.html
2018-11-12 13:54:59,681 - Not Found: /index.html
2018-11-12 13:55:05,035 - Not Found: /index.html
2018-11-12 13:55:17,451 - Internal Server Error: /go_store_out
Traceback (most recent call last):
  File "C:\Users\Administrator\venv\lib\site-packages\django\template\backends\django.py", line 61, in render
    return self.template.render(context)
  File "C:\Users\Administrator\venv\lib\site-packages\django\template\base.py", line 171, in render
    return self._render(context)
  File "C:\Users\Administrator\venv\lib\site-packages\django\template\base.py", line 163, in _render
    return self.nodelist.render(context)
  File "C:\Users\Administrator\venv\lib\site-packages\django\template\base.py", line 937, in render
    bit = node.render_annotated(context)
  File "C:\Users\Administrator\venv\lib\site-packages\django\template\base.py", line 904, in render_annotated
    return self.render(context)
  File "C:\Users\Administrator\venv\lib\site-packages\django\template\loader_tags.py", line 150, in render
    return compiled_parent._render(context)
  File "C:\Users\Administrator\venv\lib\site-packages\django\template\base.py", line 163, in _render
    return self.nodelist.render(context)
  File "C:\Users\Administrator\venv\lib\site-packages\django\template\base.py", line 937, in render
    bit = node.render_annotated(context)
  File "C:\Users\Administrator\venv\lib\site-packages\django\template\base.py", line 904, in render_annotated
    return self.render(context)
  File "C:\Users\Administrator\venv\lib\site-packages\django\template\loader_tags.py", line 62, in render
    result = block.nodelist.render(context)
  File "C:\Users\Administrator\venv\lib\site-packages\django\template\base.py", line 937, in render
    bit = node.render_annotated(context)
  File "C:\Users\Administrator\venv\lib\site-packages\django\template\base.py", line 904, in render_annotated
    return self.render(context)
  File "C:\Users\Administrator\venv\lib\site-packages\django\template\loader_tags.py", line 176, in render
    template = context.template.engine.get_template(template_name)
  File "C:\Users\Administrator\venv\lib\site-packages\django\template\engine.py", line 144, in get_template
    template, origin = self.find_template(template_name)
  File "C:\Users\Administrator\venv\lib\site-packages\django\template\engine.py", line 130, in find_template
    raise TemplateDoesNotExist(name, tried=tried)
django.template.exceptions.TemplateDoesNotExist: base/store/store_out/mainTable.html

The above exception was the direct cause of the following exception:

Traceback (most recent call last):
  File "C:\Users\Administrator\venv\lib\site-packages\django\core\handlers\exception.py", line 34, in inner
    response = get_response(request)
  File "C:\Users\Administrator\venv\lib\site-packages\django\core\handlers\base.py", line 126, in _get_response
    response = self.process_exception_by_middleware(e, request)
  File "C:\Users\Administrator\venv\lib\site-packages\django\core\handlers\base.py", line 124, in _get_response
    response = wrapped_callback(request, *callback_args, **callback_kwargs)
  File "D:\项目汇总\仓库管理\trank_\RtMonSys\views\view_store_out.py", line 12, in go_store_out
    return render(request, 'base/store/store_out/index.html')
  File "C:\Users\Administrator\venv\lib\site-packages\django\shortcuts.py", line 36, in render
    content = loader.render_to_string(template_name, context, request, using=using)
  File "C:\Users\Administrator\venv\lib\site-packages\django\template\loader.py", line 62, in render_to_string
    return template.render(context, request)
  File "C:\Users\Administrator\venv\lib\site-packages\django\template\backends\django.py", line 63, in render
    reraise(exc, self.backend)
  File "C:\Users\Administrator\venv\lib\site-packages\django\template\backends\django.py", line 84, in reraise
    raise new from exc
django.template.exceptions.TemplateDoesNotExist: base/store/store_out/mainTable.html
WARNING 2018-11-12 16:23:24,623 C:\Users\Administrator\venv\lib\site-packages\django\core\servers\basehttp.py basehttp.py basehttp log_message 124: "GET /static/resource/element/axios.min.map HTTP/1.1" 404 1714
WARNING 2018-11-12 16:23:31,939 C:\Users\Administrator\venv\lib\site-packages\django\core\servers\basehttp.py basehttp.py basehttp log_message 124: "GET /static/resource/element/axios.min.map HTTP/1.1" 404 1714
WARNING 2018-11-12 16:25:00,822 C:\Users\Administrator\venv\lib\site-packages\django\core\servers\basehttp.py basehttp.py basehttp log_message 124: "GET /static/resource/element/axios.min.map HTTP/1.1" 404 1714
WARNING 2018-11-12 16:26:03,494 C:\Users\Administrator\venv\lib\site-packages\django\core\servers\basehttp.py basehttp.py basehttp log_message 124: "GET /static/resource/element/axios.min.map HTTP/1.1" 404 1714
WARNING 2018-11-12 16:26:17,053 C:\Users\Administrator\venv\lib\site-packages\django\core\servers\basehttp.py basehttp.py basehttp log_message 124: "GET /static/resource/element/axios.min.map HTTP/1.1" 404 1714
WARNING 2018-11-12 16:26:30,389 C:\Users\Administrator\venv\lib\site-packages\django\core\servers\basehttp.py basehttp.py basehttp log_message 124: "GET /static/resource/element/axios.min.map HTTP/1.1" 404 1714
WARNING 2018-11-12 16:29:46,854 C:\Users\Administrator\venv\lib\site-packages\django\core\servers\basehttp.py basehttp.py basehttp log_message 124: "GET /static/resource/element/axios.min.map HTTP/1.1" 404 1714
WARNING 2018-11-12 16:32:14,616 C:\Users\Administrator\venv\lib\site-packages\django\core\servers\basehttp.py basehttp.py basehttp log_message 124: "GET /static/resource/element/axios.min.map HTTP/1.1" 404 1714
WARNING 2018-11-12 16:32:19,575 C:\Users\Administrator\venv\lib\site-packages\django\core\servers\basehttp.py basehttp.py basehttp log_message 124: "GET /static/resource/element/axios.min.map HTTP/1.1" 404 1714
WARNING 2018-11-12 16:32:41,797 C:\Users\Administrator\venv\lib\site-packages\django\core\servers\basehttp.py basehttp.py basehttp log_message 124: "GET /static/resource/element/axios.min.map HTTP/1.1" 404 1714
WARNING 2018-11-12 16:32:46,660 C:\Users\Administrator\venv\lib\site-packages\django\core\servers\basehttp.py basehttp.py basehttp log_message 124: "GET /static/resource/element/axios.min.map HTTP/1.1" 404 1714
WARNING 2018-11-12 17:27:41,837 C:\Users\Administrator\venv\lib\site-packages\django\core\servers\basehttp.py basehttp.py basehttp log_message 124: "GET /static/resource/element/axios.min.map HTTP/1.1" 404 1714
WARNING 2018-11-12 17:29:04,529 C:\Users\Administrator\venv\lib\site-packages\django\core\servers\basehttp.py basehttp.py basehttp log_message 124: "GET /static/resource/element/axios.min.map HTTP/1.1" 404 1714
WARNING 2018-11-12 17:33:56,287 C:\Users\Administrator\venv\lib\site-packages\django\core\servers\basehttp.py basehttp.py basehttp log_message 124: "GET /static/resource/element/axios.min.map HTTP/1.1" 404 1714
WARNING 2018-11-12 17:34:13,934 C:\Users\Administrator\venv\lib\site-packages\django\core\servers\basehttp.py basehttp.py basehttp log_message 124: "GET /static/resource/element/axios.min.map HTTP/1.1" 404 1714
WARNING 2018-11-12 17:48:33,932 C:\Users\Administrator\venv\lib\site-packages\django\core\servers\basehttp.py basehttp.py basehttp log_message 124: "GET /static/resource/element/axios.min.map HTTP/1.1" 404 1714
WARNING 2018-11-12 17:49:39,914 C:\Users\Administrator\venv\lib\site-packages\django\core\servers\basehttp.py basehttp.py basehttp log_message 124: "GET /static/resource/element/axios.min.map HTTP/1.1" 404 1714
WARNING 2018-11-12 17:49:48,426 C:\Users\Administrator\venv\lib\site-packages\django\core\servers\basehttp.py basehttp.py basehttp log_message 124: "GET /static/resource/element/axios.min.map HTTP/1.1" 404 1714
WARNING 2018-11-13 10:48:57,138 C:\Users\Administrator\venv\lib\site-packages\django\core\servers\basehttp.py basehttp.py basehttp log_message 124: "GET /static/resource/element/axios.min.map HTTP/1.1" 404 1714
WARNING 2018-11-13 10:53:23,657 C:\Users\Administrator\venv\lib\site-packages\django\core\servers\basehttp.py basehttp.py basehttp log_message 124: "GET /static/resource/element/axios.min.map HTTP/1.1" 404 1714
WARNING 2018-11-13 10:56:06,677 C:\Users\Administrator\venv\lib\site-packages\django\core\servers\basehttp.py basehttp.py basehttp log_message 124: "GET /static/resource/element/axios.min.map HTTP/1.1" 404 1714
WARNING 2018-11-13 10:56:27,096 C:\Users\Administrator\venv\lib\site-packages\django\core\servers\basehttp.py basehttp.py basehttp log_message 124: "GET /static/resource/element/axios.min.map HTTP/1.1" 404 1714
WARNING 2018-11-13 11:31:31,181 C:\Users\Administrator\venv\lib\site-packages\django\core\servers\basehttp.py basehttp.py basehttp log_message 124: "GET /static/resource/element/axios.min.map HTTP/1.1" 404 1714
WARNING 2018-11-13 11:33:59,000 C:\Users\Administrator\venv\lib\site-packages\django\core\servers\basehttp.py basehttp.py basehttp log_message 124: "GET /static/resource/element/axios.min.map HTTP/1.1" 404 1714
WARNING 2018-11-13 11:34:31,424 C:\Users\Administrator\venv\lib\site-packages\django\core\servers\basehttp.py basehttp.py basehttp log_message 124: "GET /static/resource/element/axios.min.map HTTP/1.1" 404 1714
WARNING 2018-11-13 11:43:01,343 C:\Users\Administrator\venv\lib\site-packages\django\core\servers\basehttp.py basehttp.py basehttp log_message 124: "GET /static/resource/element/axios.min.map HTTP/1.1" 404 1714
WARNING 2018-11-13 11:43:54,180 C:\Users\Administrator\venv\lib\site-packages\django\core\servers\basehttp.py basehttp.py basehttp log_message 124: "GET /static/resource/element/axios.min.map HTTP/1.1" 404 1714
WARNING 2018-11-13 11:55:46,153 C:\Users\Administrator\venv\lib\site-packages\django\core\servers\basehttp.py basehttp.py basehttp log_message 124: "GET /static/resource/element/axios.min.map HTTP/1.1" 404 1714
WARNING 2018-11-13 11:56:08,595 C:\Users\Administrator\venv\lib\site-packages\django\core\servers\basehttp.py basehttp.py basehttp log_message 124: "GET /static/resource/element/axios.min.map HTTP/1.1" 404 1714
WARNING 2018-11-13 13:22:12,587 C:\Users\Administrator\venv\lib\site-packages\django\core\servers\basehttp.py basehttp.py basehttp log_message 124: "GET /static/resource/element/axios.min.map HTTP/1.1" 404 1714
WARNING 2018-11-13 13:33:58,029 C:\Users\Administrator\venv\lib\site-packages\django\utils\log.py log.py log log_response 228: Not Found: /index.html
WARNING 2018-11-13 13:33:58,031 C:\Users\Administrator\venv\lib\site-packages\django\core\servers\basehttp.py basehttp.py basehttp log_message 124: "GET /index.html HTTP/1.1" 404 2524
WARNING 2018-11-13 14:09:52,905 C:\Users\Administrator\venv\lib\site-packages\django\core\servers\basehttp.py basehttp.py basehttp log_message 124: "GET /static/resource/element/axios.min.map HTTP/1.1" 404 1714
WARNING 2018-11-13 14:10:52,586 C:\Users\Administrator\venv\lib\site-packages\django\core\servers\basehttp.py basehttp.py basehttp log_message 124: "GET /static/resource/element/axios.min.map HTTP/1.1" 404 1714
ERROR 2018-11-13 14:11:32,731 C:\Users\Administrator\venv\lib\site-packages\django\utils\log.py log.py log log_response 228: Internal Server Error: /update_store_in/
Traceback (most recent call last):
  File "C:\Users\Administrator\venv\lib\site-packages\django\db\utils.py", line 96, in inner
    return func(*args, **kwargs)
psycopg2.ProgrammingError: no results to fetch

The above exception was the direct cause of the following exception:

Traceback (most recent call last):
  File "C:\Users\Administrator\venv\lib\site-packages\django\core\handlers\exception.py", line 34, in inner
    response = get_response(request)
  File "C:\Users\Administrator\venv\lib\site-packages\django\core\handlers\base.py", line 126, in _get_response
    response = self.process_exception_by_middleware(e, request)
  File "C:\Users\Administrator\venv\lib\site-packages\django\core\handlers\base.py", line 124, in _get_response
    response = wrapped_callback(request, *callback_args, **callback_kwargs)
  File "C:\Users\Administrator\AppData\Local\Programs\Python\Python37-32\lib\contextlib.py", line 74, in inner
    return func(*args, **kwds)
  File "D:\项目汇总\仓库管理\trank_\RtMonSys\views\view_store_in.py", line 33, in update_store_in
    createTable()
  File "D:\项目汇总\仓库管理\trank_\RtMonSys\models\model_store_in.py", line 11, in createTable
    execute(sql)
  File "D:\项目汇总\仓库管理\trank_\libs\sql.py", line 59, in execute
    rawData = cursor.fetchall()
  File "C:\Users\Administrator\venv\lib\site-packages\django\db\utils.py", line 96, in inner
    return func(*args, **kwargs)
  File "C:\Users\Administrator\venv\lib\site-packages\django\db\utils.py", line 89, in __exit__
    raise dj_exc_value.with_traceback(traceback) from exc_value
  File "C:\Users\Administrator\venv\lib\site-packages\django\db\utils.py", line 96, in inner
    return func(*args, **kwargs)
django.db.utils.ProgrammingError: no results to fetch
ERROR 2018-11-13 14:11:32,745 C:\Users\Administrator\venv\lib\site-packages\django\core\servers\basehttp.py basehttp.py basehttp log_message 124: "POST /update_store_in/ HTTP/1.1" 500 100613
ERROR 2018-11-13 14:26:16,584 C:\Users\Administrator\venv\lib\site-packages\django\utils\log.py log.py log log_response 228: Internal Server Error: /update_store_in/
Traceback (most recent call last):
  File "C:\Users\Administrator\venv\lib\site-packages\django\db\backends\utils.py", line 83, in _execute
    return self.cursor.execute(sql)
psycopg2.ProgrammingError: syntax error at or near "desc"
LINE 13:             desc varchar(50) NOT NULL,
                     ^


The above exception was the direct cause of the following exception:

Traceback (most recent call last):
  File "C:\Users\Administrator\venv\lib\site-packages\django\core\handlers\exception.py", line 34, in inner
    response = get_response(request)
  File "C:\Users\Administrator\venv\lib\site-packages\django\core\handlers\base.py", line 126, in _get_response
    response = self.process_exception_by_middleware(e, request)
  File "C:\Users\Administrator\venv\lib\site-packages\django\core\handlers\base.py", line 124, in _get_response
    response = wrapped_callback(request, *callback_args, **callback_kwargs)
  File "C:\Users\Administrator\AppData\Local\Programs\Python\Python37-32\lib\contextlib.py", line 74, in inner
    return func(*args, **kwds)
  File "D:\项目汇总\仓库管理\trank_\RtMonSys\views\view_store_in.py", line 32, in update_store_in
    model_store_in.update_store(shelves, mainTableData)
  File "D:\项目汇总\仓库管理\trank_\RtMonSys\models\model_store_in.py", line 30, in update_store
    createTable()
  File "D:\项目汇总\仓库管理\trank_\RtMonSys\models\model_store_in.py", line 27, in createTable
    insert_update(sql)
  File "D:\项目汇总\仓库管理\trank_\libs\sql.py", line 67, in insert_update
    cursor.execute(sql, params)
  File "C:\Users\Administrator\venv\lib\site-packages\django\db\backends\utils.py", line 100, in execute
    return super().execute(sql, params)
  File "C:\Users\Administrator\venv\lib\site-packages\django\db\backends\utils.py", line 68, in execute
    return self._execute_with_wrappers(sql, params, many=False, executor=self._execute)
  File "C:\Users\Administrator\venv\lib\site-packages\django\db\backends\utils.py", line 77, in _execute_with_wrappers
    return executor(sql, params, many, context)
  File "C:\Users\Administrator\venv\lib\site-packages\django\db\backends\utils.py", line 85, in _execute
    return self.cursor.execute(sql, params)
  File "C:\Users\Administrator\venv\lib\site-packages\django\db\utils.py", line 89, in __exit__
    raise dj_exc_value.with_traceback(traceback) from exc_value
  File "C:\Users\Administrator\venv\lib\site-packages\django\db\backends\utils.py", line 83, in _execute
    return self.cursor.execute(sql)
django.db.utils.ProgrammingError: syntax error at or near "desc"
LINE 13:             desc varchar(50) NOT NULL,
                     ^

ERROR 2018-11-13 14:26:16,601 C:\Users\Administrator\venv\lib\site-packages\django\core\servers\basehttp.py basehttp.py basehttp log_message 124: "POST /update_store_in/ HTTP/1.1" 500 127852
ERROR 2018-11-13 14:40:51,608 C:\Users\Administrator\venv\lib\site-packages\django\utils\log.py log.py log log_response 228: Internal Server Error: /update_store_in/
Traceback (most recent call last):
  File "C:\Users\Administrator\venv\lib\site-packages\django\core\handlers\exception.py", line 34, in inner
    response = get_response(request)
  File "C:\Users\Administrator\venv\lib\site-packages\django\core\handlers\base.py", line 126, in _get_response
    response = self.process_exception_by_middleware(e, request)
  File "C:\Users\Administrator\venv\lib\site-packages\django\core\handlers\base.py", line 124, in _get_response
    response = wrapped_callback(request, *callback_args, **callback_kwargs)
  File "C:\Users\Administrator\AppData\Local\Programs\Python\Python37-32\lib\contextlib.py", line 74, in inner
    return func(*args, **kwds)
  File "D:\项目汇总\仓库管理\trank_\RtMonSys\views\view_store_in.py", line 32, in update_store_in
    model_store_in.update_store(searchData, mainTableData)
  File "D:\项目汇总\仓库管理\trank_\RtMonSys\models\model_store_in.py", line 34, in update_store
    rows = execute(sql,(mainTableData['bp_n'],))
TypeError: list indices must be integers or slices, not str
ERROR 2018-11-13 14:40:51,615 C:\Users\Administrator\venv\lib\site-packages\django\core\servers\basehttp.py basehttp.py basehttp log_message 124: "POST /update_store_in/ HTTP/1.1" 500 82237
ERROR 2018-11-13 14:42:35,193 C:\Users\Administrator\venv\lib\site-packages\django\utils\log.py log.py log log_response 228: Internal Server Error: /update_store_in/
Traceback (most recent call last):
  File "C:\Users\Administrator\venv\lib\site-packages\django\core\handlers\exception.py", line 34, in inner
    response = get_response(request)
  File "C:\Users\Administrator\venv\lib\site-packages\django\core\handlers\base.py", line 126, in _get_response
    response = self.process_exception_by_middleware(e, request)
  File "C:\Users\Administrator\venv\lib\site-packages\django\core\handlers\base.py", line 124, in _get_response
    response = wrapped_callback(request, *callback_args, **callback_kwargs)
  File "C:\Users\Administrator\AppData\Local\Programs\Python\Python37-32\lib\contextlib.py", line 74, in inner
    return func(*args, **kwds)
  File "D:\项目汇总\仓库管理\trank_\RtMonSys\views\view_store_in.py", line 32, in update_store_in
    model_store_in.update_store(searchData, mainTableData)
  File "D:\项目汇总\仓库管理\trank_\RtMonSys\models\model_store_in.py", line 33, in update_store
    sql = '''SELECT count(1) FROM store WHERE bp_n=%s'''%(mainTableData['bp_n'])
TypeError: list indices must be integers or slices, not str
ERROR 2018-11-13 14:42:35,203 C:\Users\Administrator\venv\lib\site-packages\django\core\servers\basehttp.py basehttp.py basehttp log_message 124: "POST /update_store_in/ HTTP/1.1" 500 82033
WARNING 2018-11-13 14:42:47,510 C:\Users\Administrator\venv\lib\site-packages\django\core\servers\basehttp.py basehttp.py basehttp log_message 124: "GET /static/resource/element/axios.min.map HTTP/1.1" 404 1714
ERROR 2018-11-13 14:42:50,430 C:\Users\Administrator\venv\lib\site-packages\django\utils\log.py log.py log log_response 228: Internal Server Error: /update_store_in/
Traceback (most recent call last):
  File "C:\Users\Administrator\venv\lib\site-packages\django\core\handlers\exception.py", line 34, in inner
    response = get_response(request)
  File "C:\Users\Administrator\venv\lib\site-packages\django\core\handlers\base.py", line 126, in _get_response
    response = self.process_exception_by_middleware(e, request)
  File "C:\Users\Administrator\venv\lib\site-packages\django\core\handlers\base.py", line 124, in _get_response
    response = wrapped_callback(request, *callback_args, **callback_kwargs)
  File "C:\Users\Administrator\AppData\Local\Programs\Python\Python37-32\lib\contextlib.py", line 74, in inner
    return func(*args, **kwds)
  File "D:\项目汇总\仓库管理\trank_\RtMonSys\views\view_store_in.py", line 29, in update_store_in
    params = json.loads(request.body.decode('utf-8'))
  File "C:\Users\Administrator\AppData\Local\Programs\Python\Python37-32\lib\json\__init__.py", line 348, in loads
    return _default_decoder.decode(s)
  File "C:\Users\Administrator\AppData\Local\Programs\Python\Python37-32\lib\json\decoder.py", line 337, in decode
    obj, end = self.raw_decode(s, idx=_w(s, 0).end())
  File "C:\Users\Administrator\AppData\Local\Programs\Python\Python37-32\lib\json\decoder.py", line 355, in raw_decode
    raise JSONDecodeError("Expecting value", s, err.value) from None
json.decoder.JSONDecodeError: Expecting value: line 1 column 1 (char 0)
ERROR 2018-11-13 14:42:50,439 C:\Users\Administrator\venv\lib\site-packages\django\core\servers\basehttp.py basehttp.py basehttp log_message 124: "GET /update_store_in/ HTTP/1.1" 500 90070
WARNING 2018-11-13 14:43:38,362 C:\Users\Administrator\venv\lib\site-packages\django\core\servers\basehttp.py basehttp.py basehttp log_message 124: "GET /static/resource/element/axios.min.map HTTP/1.1" 404 1714
WARNING 2018-11-13 14:45:41,229 C:\Users\Administrator\venv\lib\site-packages\django\core\servers\basehttp.py basehttp.py basehttp log_message 124: "GET /static/resource/element/axios.min.map HTTP/1.1" 404 1714
ERROR 2018-11-13 14:46:00,485 C:\Users\Administrator\venv\lib\site-packages\django\utils\log.py log.py log log_response 228: Internal Server Error: /update_store_in/
Traceback (most recent call last):
  File "C:\Users\Administrator\venv\lib\site-packages\django\core\handlers\exception.py", line 34, in inner
    response = get_response(request)
  File "C:\Users\Administrator\venv\lib\site-packages\django\core\handlers\base.py", line 126, in _get_response
    response = self.process_exception_by_middleware(e, request)
  File "C:\Users\Administrator\venv\lib\site-packages\django\core\handlers\base.py", line 124, in _get_response
    response = wrapped_callback(request, *callback_args, **callback_kwargs)
  File "C:\Users\Administrator\AppData\Local\Programs\Python\Python37-32\lib\contextlib.py", line 74, in inner
    return func(*args, **kwds)
  File "D:\项目汇总\仓库管理\trank_\RtMonSys\views\view_store_in.py", line 32, in update_store_in
    model_store_in.update_store(searchData, mainTableData)
  File "D:\项目汇总\仓库管理\trank_\RtMonSys\models\model_store_in.py", line 34, in update_store
    rows = execute(sql,mainTableData[0]['bp_n'])
  File "D:\项目汇总\仓库管理\trank_\libs\sql.py", line 58, in execute
    cursor.execute(sql, params)
  File "C:\Users\Administrator\venv\lib\site-packages\django\db\backends\utils.py", line 100, in execute
    return super().execute(sql, params)
  File "C:\Users\Administrator\venv\lib\site-packages\django\db\backends\utils.py", line 68, in execute
    return self._execute_with_wrappers(sql, params, many=False, executor=self._execute)
  File "C:\Users\Administrator\venv\lib\site-packages\django\db\backends\utils.py", line 77, in _execute_with_wrappers
    return executor(sql, params, many, context)
  File "C:\Users\Administrator\venv\lib\site-packages\django\db\backends\utils.py", line 85, in _execute
    return self.cursor.execute(sql, params)
TypeError: not all arguments converted during string formatting
ERROR 2018-11-13 14:46:00,492 C:\Users\Administrator\venv\lib\site-packages\django\core\servers\basehttp.py basehttp.py basehttp log_message 124: "POST /update_store_in/ HTTP/1.1" 500 103645
WARNING 2018-11-13 14:46:54,512 C:\Users\Administrator\venv\lib\site-packages\django\core\servers\basehttp.py basehttp.py basehttp log_message 124: "GET /static/resource/element/axios.min.map HTTP/1.1" 404 1714
ERROR 2018-11-13 14:47:18,030 C:\Users\Administrator\venv\lib\site-packages\django\utils\log.py log.py log log_response 228: Internal Server Error: /update_store_in/
Traceback (most recent call last):
  File "C:\Users\Administrator\venv\lib\site-packages\django\db\backends\utils.py", line 83, in _execute
    return self.cursor.execute(sql)
psycopg2.ProgrammingError: column "b" does not exist
LINE 1: SELECT count(1) FROM store WHERE bp_n=806-07904-B
                                                        ^


The above exception was the direct cause of the following exception:

Traceback (most recent call last):
  File "C:\Users\Administrator\venv\lib\site-packages\django\core\handlers\exception.py", line 34, in inner
    response = get_response(request)
  File "C:\Users\Administrator\venv\lib\site-packages\django\core\handlers\base.py", line 126, in _get_response
    response = self.process_exception_by_middleware(e, request)
  File "C:\Users\Administrator\venv\lib\site-packages\django\core\handlers\base.py", line 124, in _get_response
    response = wrapped_callback(request, *callback_args, **callback_kwargs)
  File "C:\Users\Administrator\AppData\Local\Programs\Python\Python37-32\lib\contextlib.py", line 74, in inner
    return func(*args, **kwds)
  File "D:\项目汇总\仓库管理\trank_\RtMonSys\views\view_store_in.py", line 32, in update_store_in
    model_store_in.update_store(searchData, mainTableData)
  File "D:\项目汇总\仓库管理\trank_\RtMonSys\models\model_store_in.py", line 34, in update_store
    rows = execute(sql)
  File "D:\项目汇总\仓库管理\trank_\libs\sql.py", line 58, in execute
    cursor.execute(sql, params)
  File "C:\Users\Administrator\venv\lib\site-packages\django\db\backends\utils.py", line 100, in execute
    return super().execute(sql, params)
  File "C:\Users\Administrator\venv\lib\site-packages\django\db\backends\utils.py", line 68, in execute
    return self._execute_with_wrappers(sql, params, many=False, executor=self._execute)
  File "C:\Users\Administrator\venv\lib\site-packages\django\db\backends\utils.py", line 77, in _execute_with_wrappers
    return executor(sql, params, many, context)
  File "C:\Users\Administrator\venv\lib\site-packages\django\db\backends\utils.py", line 85, in _execute
    return self.cursor.execute(sql, params)
  File "C:\Users\Administrator\venv\lib\site-packages\django\db\utils.py", line 89, in __exit__
    raise dj_exc_value.with_traceback(traceback) from exc_value
  File "C:\Users\Administrator\venv\lib\site-packages\django\db\backends\utils.py", line 83, in _execute
    return self.cursor.execute(sql)
django.db.utils.ProgrammingError: column "b" does not exist
LINE 1: SELECT count(1) FROM store WHERE bp_n=806-07904-B
                                                        ^

ERROR 2018-11-13 14:47:18,038 C:\Users\Administrator\venv\lib\site-packages\django\core\servers\basehttp.py basehttp.py basehttp log_message 124: "POST /update_store_in/ HTTP/1.1" 500 118511
WARNING 2018-11-13 14:47:35,274 C:\Users\Administrator\venv\lib\site-packages\django\core\servers\basehttp.py basehttp.py basehttp log_message 124: "GET /static/resource/element/axios.min.map HTTP/1.1" 404 1714
WARNING 2018-11-13 14:49:52,747 C:\Users\Administrator\venv\lib\site-packages\django\core\servers\basehttp.py basehttp.py basehttp log_message 124: "GET /static/resource/element/axios.min.map HTTP/1.1" 404 1714
ERROR 2018-11-13 14:50:27,286 C:\Users\Administrator\venv\lib\site-packages\django\utils\log.py log.py log log_response 228: Internal Server Error: /update_store_in/
Traceback (most recent call last):
  File "C:\Users\Administrator\venv\lib\site-packages\django\db\backends\utils.py", line 83, in _execute
    return self.cursor.execute(sql)
psycopg2.ProgrammingError: column "b" does not exist
LINE 1: SELECT count(1) FROM store WHERE bp_n=806-07904-B
                                                        ^


The above exception was the direct cause of the following exception:

Traceback (most recent call last):
  File "C:\Users\Administrator\venv\lib\site-packages\django\core\handlers\exception.py", line 34, in inner
    response = get_response(request)
  File "C:\Users\Administrator\venv\lib\site-packages\django\core\handlers\base.py", line 126, in _get_response
    response = self.process_exception_by_middleware(e, request)
  File "C:\Users\Administrator\venv\lib\site-packages\django\core\handlers\base.py", line 124, in _get_response
    response = wrapped_callback(request, *callback_args, **callback_kwargs)
  File "C:\Users\Administrator\AppData\Local\Programs\Python\Python37-32\lib\contextlib.py", line 74, in inner
    return func(*args, **kwds)
  File "D:\项目汇总\仓库管理\trank_\RtMonSys\views\view_store_in.py", line 32, in update_store_in
    model_store_in.update_store(searchData, mainTableData)
  File "D:\项目汇总\仓库管理\trank_\RtMonSys\models\model_store_in.py", line 34, in update_store
    rows = execute(sql)
  File "D:\项目汇总\仓库管理\trank_\libs\sql.py", line 58, in execute
    cursor.execute(sql, params)
  File "C:\Users\Administrator\venv\lib\site-packages\django\db\backends\utils.py", line 100, in execute
    return super().execute(sql, params)
  File "C:\Users\Administrator\venv\lib\site-packages\django\db\backends\utils.py", line 68, in execute
    return self._execute_with_wrappers(sql, params, many=False, executor=self._execute)
  File "C:\Users\Administrator\venv\lib\site-packages\django\db\backends\utils.py", line 77, in _execute_with_wrappers
    return executor(sql, params, many, context)
  File "C:\Users\Administrator\venv\lib\site-packages\django\db\backends\utils.py", line 85, in _execute
    return self.cursor.execute(sql, params)
  File "C:\Users\Administrator\venv\lib\site-packages\django\db\utils.py", line 89, in __exit__
    raise dj_exc_value.with_traceback(traceback) from exc_value
  File "C:\Users\Administrator\venv\lib\site-packages\django\db\backends\utils.py", line 83, in _execute
    return self.cursor.execute(sql)
django.db.utils.ProgrammingError: column "b" does not exist
LINE 1: SELECT count(1) FROM store WHERE bp_n=806-07904-B
                                                        ^

ERROR 2018-11-13 14:50:27,289 C:\Users\Administrator\venv\lib\site-packages\django\core\servers\basehttp.py basehttp.py basehttp log_message 124: "POST /update_store_in/ HTTP/1.1" 500 119647
ERROR 2018-11-13 14:54:08,922 C:\Users\Administrator\venv\lib\site-packages\django\utils\log.py log.py log log_response 228: Internal Server Error: /update_store_in/
Traceback (most recent call last):
  File "C:\Users\Administrator\venv\lib\site-packages\django\core\handlers\exception.py", line 34, in inner
    response = get_response(request)
  File "C:\Users\Administrator\venv\lib\site-packages\django\core\handlers\base.py", line 126, in _get_response
    response = self.process_exception_by_middleware(e, request)
  File "C:\Users\Administrator\venv\lib\site-packages\django\core\handlers\base.py", line 124, in _get_response
    response = wrapped_callback(request, *callback_args, **callback_kwargs)
  File "C:\Users\Administrator\AppData\Local\Programs\Python\Python37-32\lib\contextlib.py", line 74, in inner
    return func(*args, **kwds)
  File "D:\项目汇总\仓库管理\trank_\RtMonSys\views\view_store_in.py", line 32, in update_store_in
    model_store_in.update_store(searchData, mainTableData)
  File "D:\项目汇总\仓库管理\trank_\RtMonSys\models\model_store_in.py", line 34, in update_store
    rows = execute(sql,(mainTableData[0]['bp_n']))
  File "D:\项目汇总\仓库管理\trank_\libs\sql.py", line 58, in execute
    cursor.execute(sql, params)
  File "C:\Users\Administrator\venv\lib\site-packages\django\db\backends\utils.py", line 100, in execute
    return super().execute(sql, params)
  File "C:\Users\Administrator\venv\lib\site-packages\django\db\backends\utils.py", line 68, in execute
    return self._execute_with_wrappers(sql, params, many=False, executor=self._execute)
  File "C:\Users\Administrator\venv\lib\site-packages\django\db\backends\utils.py", line 77, in _execute_with_wrappers
    return executor(sql, params, many, context)
  File "C:\Users\Administrator\venv\lib\site-packages\django\db\backends\utils.py", line 85, in _execute
    return self.cursor.execute(sql, params)
TypeError: not all arguments converted during string formatting
ERROR 2018-11-13 14:54:08,935 C:\Users\Administrator\venv\lib\site-packages\django\core\servers\basehttp.py basehttp.py basehttp log_message 124: "POST /update_store_in/ HTTP/1.1" 500 103531
WARNING 2018-11-13 15:13:22,774 C:\Users\Administrator\venv\lib\site-packages\django\core\servers\basehttp.py basehttp.py basehttp log_message 124: "GET /static/resource/element/axios.min.map HTTP/1.1" 404 1714
WARNING 2018-11-13 15:14:37,661 C:\Users\Administrator\venv\lib\site-packages\django\core\servers\basehttp.py basehttp.py basehttp log_message 124: "GET /static/resource/element/axios.min.map HTTP/1.1" 404 1714
WARNING 2018-11-13 15:28:35,850 C:\Users\Administrator\venv\lib\site-packages\django\core\servers\basehttp.py basehttp.py basehttp log_message 124: "GET /static/resource/element/axios.min.map HTTP/1.1" 404 1714
WARNING 2018-11-13 15:29:09,632 C:\Users\Administrator\venv\lib\site-packages\django\core\servers\basehttp.py basehttp.py basehttp log_message 124: "GET /static/resource/element/axios.min.map HTTP/1.1" 404 1714
WARNING 2018-11-13 16:43:30,438 C:\Users\Administrator\venv\lib\site-packages\django\core\servers\basehttp.py basehttp.py basehttp log_message 124: "GET /static/config/config.js HTTP/1.1" 404 1672
WARNING 2018-11-13 16:43:30,926 C:\Users\Administrator\venv\lib\site-packages\django\core\servers\basehttp.py basehttp.py basehttp log_message 124: "GET /static/config/config.js HTTP/1.1" 404 1672
WARNING 2018-11-13 17:27:57,312 C:\Users\Administrator\venv\lib\site-packages\django\core\servers\basehttp.py basehttp.py basehttp log_message 124: "GET /static/config/config.js HTTP/1.1" 404 1672
WARNING 2018-11-13 17:27:58,229 C:\Users\Administrator\venv\lib\site-packages\django\core\servers\basehttp.py basehttp.py basehttp log_message 124: "GET /static/config/config.js HTTP/1.1" 404 1672
WARNING 2018-11-14 10:10:36,317 C:\Users\Administrator\venv\lib\site-packages\django\core\servers\basehttp.py basehttp.py basehttp log_message 124: "GET /static/resource/element/axios.min.map HTTP/1.1" 404 1714
WARNING 2018-11-14 10:11:05,779 C:\Users\Administrator\venv\lib\site-packages\django\core\servers\basehttp.py basehttp.py basehttp log_message 124: "GET /static/resource/element/axios.min.map HTTP/1.1" 404 1714
WARNING 2018-11-14 10:11:47,462 C:\Users\Administrator\venv\lib\site-packages\django\core\servers\basehttp.py basehttp.py basehttp log_message 124: "GET /static/resource/element/axios.min.map HTTP/1.1" 404 1714
ERROR 2018-11-14 10:11:52,752 C:\Users\Administrator\venv\lib\site-packages\django\utils\log.py log.py log log_response 228: Internal Server Error: /search_config/
Traceback (most recent call last):
  File "C:\Users\Administrator\venv\lib\site-packages\django\db\backends\utils.py", line 83, in _execute
    return self.cursor.execute(sql)
psycopg2.ProgrammingError: column "name" does not exist
LINE 1: SELECT name,usage,chinese_name,apn,rev,vendor,qty,config，re...
               ^


The above exception was the direct cause of the following exception:

Traceback (most recent call last):
  File "C:\Users\Administrator\venv\lib\site-packages\django\core\handlers\exception.py", line 34, in inner
    response = get_response(request)
  File "C:\Users\Administrator\venv\lib\site-packages\django\core\handlers\base.py", line 126, in _get_response
    response = self.process_exception_by_middleware(e, request)
  File "C:\Users\Administrator\venv\lib\site-packages\django\core\handlers\base.py", line 124, in _get_response
    response = wrapped_callback(request, *callback_args, **callback_kwargs)
  File "C:\Users\Administrator\AppData\Local\Programs\Python\Python37-32\lib\contextlib.py", line 74, in inner
    return func(*args, **kwds)
  File "D:\项目汇总\仓库管理\trank_\RtMonSys\views\view_store_out.py", line 35, in search_config
    results = model_store_out.search_config(searchData, start, end)
  File "D:\项目汇总\仓库管理\trank_\RtMonSys\models\model_store_out.py", line 8, in search_config
    results = query(sql_num)
  File "D:\项目汇总\仓库管理\trank_\libs\sql.py", line 14, in query
    cursor.execute(sql, params)
  File "C:\Users\Administrator\venv\lib\site-packages\django\db\backends\utils.py", line 100, in execute
    return super().execute(sql, params)
  File "C:\Users\Administrator\venv\lib\site-packages\django\db\backends\utils.py", line 68, in execute
    return self._execute_with_wrappers(sql, params, many=False, executor=self._execute)
  File "C:\Users\Administrator\venv\lib\site-packages\django\db\backends\utils.py", line 77, in _execute_with_wrappers
    return executor(sql, params, many, context)
  File "C:\Users\Administrator\venv\lib\site-packages\django\db\backends\utils.py", line 85, in _execute
    return self.cursor.execute(sql, params)
  File "C:\Users\Administrator\venv\lib\site-packages\django\db\utils.py", line 89, in __exit__
    raise dj_exc_value.with_traceback(traceback) from exc_value
  File "C:\Users\Administrator\venv\lib\site-packages\django\db\backends\utils.py", line 83, in _execute
    return self.cursor.execute(sql)
django.db.utils.ProgrammingError: column "name" does not exist
LINE 1: SELECT name,usage,chinese_name,apn,rev,vendor,qty,config，re...
               ^

ERROR 2018-11-14 10:11:52,763 C:\Users\Administrator\venv\lib\site-packages\django\core\servers\basehttp.py basehttp.py basehttp log_message 124: "POST /search_config/ HTTP/1.1" 500 116802
WARNING 2018-11-14 10:11:55,923 C:\Users\Administrator\venv\lib\site-packages\django\core\servers\basehttp.py basehttp.py basehttp log_message 124: "GET /static/resource/element/axios.min.map HTTP/1.1" 404 1714
ERROR 2018-11-14 10:11:58,391 C:\Users\Administrator\venv\lib\site-packages\django\utils\log.py log.py log log_response 228: Internal Server Error: /search_config/
Traceback (most recent call last):
  File "C:\Users\Administrator\venv\lib\site-packages\django\core\handlers\exception.py", line 34, in inner
    response = get_response(request)
  File "C:\Users\Administrator\venv\lib\site-packages\django\core\handlers\base.py", line 126, in _get_response
    response = self.process_exception_by_middleware(e, request)
  File "C:\Users\Administrator\venv\lib\site-packages\django\core\handlers\base.py", line 124, in _get_response
    response = wrapped_callback(request, *callback_args, **callback_kwargs)
  File "C:\Users\Administrator\AppData\Local\Programs\Python\Python37-32\lib\contextlib.py", line 74, in inner
    return func(*args, **kwds)
  File "D:\项目汇总\仓库管理\trank_\RtMonSys\views\view_store_out.py", line 28, in search_config
    params = json.loads(request.body.decode('utf-8'))
  File "C:\Users\Administrator\AppData\Local\Programs\Python\Python37-32\lib\json\__init__.py", line 348, in loads
    return _default_decoder.decode(s)
  File "C:\Users\Administrator\AppData\Local\Programs\Python\Python37-32\lib\json\decoder.py", line 337, in decode
    obj, end = self.raw_decode(s, idx=_w(s, 0).end())
  File "C:\Users\Administrator\AppData\Local\Programs\Python\Python37-32\lib\json\decoder.py", line 355, in raw_decode
    raise JSONDecodeError("Expecting value", s, err.value) from None
json.decoder.JSONDecodeError: Expecting value: line 1 column 1 (char 0)
ERROR 2018-11-14 10:11:58,396 C:\Users\Administrator\venv\lib\site-packages\django\core\servers\basehttp.py basehttp.py basehttp log_message 124: "GET /search_config/ HTTP/1.1" 500 90292
ERROR 2018-11-14 10:12:49,285 C:\Users\Administrator\venv\lib\site-packages\django\utils\log.py log.py log log_response 228: Internal Server Error: /search_config/
Traceback (most recent call last):
  File "C:\Users\Administrator\venv\lib\site-packages\django\db\backends\utils.py", line 83, in _execute
    return self.cursor.execute(sql)
psycopg2.ProgrammingError: column "name" does not exist
LINE 1: SELECT name,usage,chinese_name,apn,rev,vendor,qty,config，re...
               ^


The above exception was the direct cause of the following exception:

Traceback (most recent call last):
  File "C:\Users\Administrator\venv\lib\site-packages\django\core\handlers\exception.py", line 34, in inner
    response = get_response(request)
  File "C:\Users\Administrator\venv\lib\site-packages\django\core\handlers\base.py", line 126, in _get_response
    response = self.process_exception_by_middleware(e, request)
  File "C:\Users\Administrator\venv\lib\site-packages\django\core\handlers\base.py", line 124, in _get_response
    response = wrapped_callback(request, *callback_args, **callback_kwargs)
  File "C:\Users\Administrator\AppData\Local\Programs\Python\Python37-32\lib\contextlib.py", line 74, in inner
    return func(*args, **kwds)
  File "D:\项目汇总\仓库管理\trank_\RtMonSys\views\view_store_out.py", line 35, in search_config
    results = model_store_out.search_config(searchData, start, end)
  File "D:\项目汇总\仓库管理\trank_\RtMonSys\models\model_store_out.py", line 8, in search_config
    results = query(sql_num)
  File "D:\项目汇总\仓库管理\trank_\libs\sql.py", line 14, in query
    cursor.execute(sql, params)
  File "C:\Users\Administrator\venv\lib\site-packages\django\db\backends\utils.py", line 100, in execute
    return super().execute(sql, params)
  File "C:\Users\Administrator\venv\lib\site-packages\django\db\backends\utils.py", line 68, in execute
    return self._execute_with_wrappers(sql, params, many=False, executor=self._execute)
  File "C:\Users\Administrator\venv\lib\site-packages\django\db\backends\utils.py", line 77, in _execute_with_wrappers
    return executor(sql, params, many, context)
  File "C:\Users\Administrator\venv\lib\site-packages\django\db\backends\utils.py", line 85, in _execute
    return self.cursor.execute(sql, params)
  File "C:\Users\Administrator\venv\lib\site-packages\django\db\utils.py", line 89, in __exit__
    raise dj_exc_value.with_traceback(traceback) from exc_value
  File "C:\Users\Administrator\venv\lib\site-packages\django\db\backends\utils.py", line 83, in _execute
    return self.cursor.execute(sql)
django.db.utils.ProgrammingError: column "name" does not exist
LINE 1: SELECT name,usage,chinese_name,apn,rev,vendor,qty,config，re...
               ^

ERROR 2018-11-14 10:12:49,294 C:\Users\Administrator\venv\lib\site-packages\django\core\servers\basehttp.py basehttp.py basehttp log_message 124: "POST /search_config/ HTTP/1.1" 500 117308
ERROR 2018-11-14 10:14:10,954 C:\Users\Administrator\venv\lib\site-packages\django\utils\log.py log.py log log_response 228: Internal Server Error: /search_config/
Traceback (most recent call last):
  File "C:\Users\Administrator\venv\lib\site-packages\django\db\backends\utils.py", line 83, in _execute
    return self.cursor.execute(sql)
psycopg2.ProgrammingError: column "config，remark" does not exist
LINE 1: SELECT name,usage,chinese_name,apn,rev,vendor,qty,config，re...
                                                          ^


The above exception was the direct cause of the following exception:

Traceback (most recent call last):
  File "C:\Users\Administrator\venv\lib\site-packages\django\core\handlers\exception.py", line 34, in inner
    response = get_response(request)
  File "C:\Users\Administrator\venv\lib\site-packages\django\core\handlers\base.py", line 126, in _get_response
    response = self.process_exception_by_middleware(e, request)
  File "C:\Users\Administrator\venv\lib\site-packages\django\core\handlers\base.py", line 124, in _get_response
    response = wrapped_callback(request, *callback_args, **callback_kwargs)
  File "C:\Users\Administrator\AppData\Local\Programs\Python\Python37-32\lib\contextlib.py", line 74, in inner
    return func(*args, **kwds)
  File "D:\项目汇总\仓库管理\trank_\RtMonSys\views\view_store_out.py", line 35, in search_config
    results = model_store_out.search_config(searchData, start, end)
  File "D:\项目汇总\仓库管理\trank_\RtMonSys\models\model_store_out.py", line 8, in search_config
    results = query(sql_num)
  File "D:\项目汇总\仓库管理\trank_\libs\sql.py", line 14, in query
    cursor.execute(sql, params)
  File "C:\Users\Administrator\venv\lib\site-packages\django\db\backends\utils.py", line 100, in execute
    return super().execute(sql, params)
  File "C:\Users\Administrator\venv\lib\site-packages\django\db\backends\utils.py", line 68, in execute
    return self._execute_with_wrappers(sql, params, many=False, executor=self._execute)
  File "C:\Users\Administrator\venv\lib\site-packages\django\db\backends\utils.py", line 77, in _execute_with_wrappers
    return executor(sql, params, many, context)
  File "C:\Users\Administrator\venv\lib\site-packages\django\db\backends\utils.py", line 85, in _execute
    return self.cursor.execute(sql, params)
  File "C:\Users\Administrator\venv\lib\site-packages\django\db\utils.py", line 89, in __exit__
    raise dj_exc_value.with_traceback(traceback) from exc_value
  File "C:\Users\Administrator\venv\lib\site-packages\django\db\backends\utils.py", line 83, in _execute
    return self.cursor.execute(sql)
django.db.utils.ProgrammingError: column "config，remark" does not exist
LINE 1: SELECT name,usage,chinese_name,apn,rev,vendor,qty,config，re...
                                                          ^

ERROR 2018-11-14 10:14:10,958 C:\Users\Administrator\venv\lib\site-packages\django\core\servers\basehttp.py basehttp.py basehttp log_message 124: "POST /search_config/ HTTP/1.1" 500 117232
ERROR 2018-11-14 10:14:36,284 C:\Users\Administrator\venv\lib\site-packages\django\utils\log.py log.py log log_response 228: Internal Server Error: /search_config/
Traceback (most recent call last):
  File "C:\Users\Administrator\venv\lib\site-packages\django\core\handlers\exception.py", line 34, in inner
    response = get_response(request)
  File "C:\Users\Administrator\venv\lib\site-packages\django\core\handlers\base.py", line 137, in _get_response
    "returned None instead." % (callback.__module__, view_name)
ValueError: The view RtMonSys.views.view_store_out.search_config didn't return an HttpResponse object. It returned None instead.
ERROR 2018-11-14 10:14:36,287 C:\Users\Administrator\venv\lib\site-packages\django\core\servers\basehttp.py basehttp.py basehttp log_message 124: "POST /search_config/ HTTP/1.1" 500 62804
WARNING 2018-11-14 10:14:41,996 C:\Users\Administrator\venv\lib\site-packages\django\core\servers\basehttp.py basehttp.py basehttp log_message 124: "GET /static/resource/element/axios.min.map HTTP/1.1" 404 1714
ERROR 2018-11-14 10:14:43,852 C:\Users\Administrator\venv\lib\site-packages\django\utils\log.py log.py log log_response 228: Internal Server Error: /search_config/
Traceback (most recent call last):
  File "C:\Users\Administrator\venv\lib\site-packages\django\core\handlers\exception.py", line 34, in inner
    response = get_response(request)
  File "C:\Users\Administrator\venv\lib\site-packages\django\core\handlers\base.py", line 126, in _get_response
    response = self.process_exception_by_middleware(e, request)
  File "C:\Users\Administrator\venv\lib\site-packages\django\core\handlers\base.py", line 124, in _get_response
    response = wrapped_callback(request, *callback_args, **callback_kwargs)
  File "C:\Users\Administrator\AppData\Local\Programs\Python\Python37-32\lib\contextlib.py", line 74, in inner
    return func(*args, **kwds)
  File "D:\项目汇总\仓库管理\trank_\RtMonSys\views\view_store_out.py", line 28, in search_config
    params = json.loads(request.body.decode('utf-8'))
  File "C:\Users\Administrator\AppData\Local\Programs\Python\Python37-32\lib\json\__init__.py", line 348, in loads
    return _default_decoder.decode(s)
  File "C:\Users\Administrator\AppData\Local\Programs\Python\Python37-32\lib\json\decoder.py", line 337, in decode
    obj, end = self.raw_decode(s, idx=_w(s, 0).end())
  File "C:\Users\Administrator\AppData\Local\Programs\Python\Python37-32\lib\json\decoder.py", line 355, in raw_decode
    raise JSONDecodeError("Expecting value", s, err.value) from None
json.decoder.JSONDecodeError: Expecting value: line 1 column 1 (char 0)
ERROR 2018-11-14 10:14:43,861 C:\Users\Administrator\venv\lib\site-packages\django\core\servers\basehttp.py basehttp.py basehttp log_message 124: "GET /search_config/ HTTP/1.1" 500 90038
WARNING 2018-11-14 10:15:11,674 C:\Users\Administrator\venv\lib\site-packages\django\core\servers\basehttp.py basehttp.py basehttp log_message 124: "GET /static/resource/element/axios.min.map HTTP/1.1" 404 1714
ERROR 2018-11-14 10:15:22,347 C:\Users\Administrator\venv\lib\site-packages\django\utils\log.py log.py log log_response 228: Internal Server Error: /search_config/
Traceback (most recent call last):
  File "C:\Users\Administrator\venv\lib\site-packages\django\core\handlers\exception.py", line 34, in inner
    response = get_response(request)
  File "C:\Users\Administrator\venv\lib\site-packages\django\core\handlers\base.py", line 137, in _get_response
    "returned None instead." % (callback.__module__, view_name)
ValueError: The view RtMonSys.views.view_store_out.search_config didn't return an HttpResponse object. It returned None instead.
ERROR 2018-11-14 10:15:22,350 C:\Users\Administrator\venv\lib\site-packages\django\core\servers\basehttp.py basehttp.py basehttp log_message 124: "POST /search_config/ HTTP/1.1" 500 62870
WARNING 2018-11-14 10:15:33,199 C:\Users\Administrator\venv\lib\site-packages\django\core\servers\basehttp.py basehttp.py basehttp log_message 124: "GET /static/resource/element/axios.min.map HTTP/1.1" 404 1714
ERROR 2018-11-14 10:15:48,433 C:\Users\Administrator\venv\lib\site-packages\django\utils\log.py log.py log log_response 228: Internal Server Error: /search_config/
Traceback (most recent call last):
  File "C:\Users\Administrator\venv\lib\site-packages\django\core\handlers\exception.py", line 34, in inner
    response = get_response(request)
  File "C:\Users\Administrator\venv\lib\site-packages\django\core\handlers\base.py", line 137, in _get_response
    "returned None instead." % (callback.__module__, view_name)
ValueError: The view RtMonSys.views.view_store_out.search_config didn't return an HttpResponse object. It returned None instead.
ERROR 2018-11-14 10:15:48,438 C:\Users\Administrator\venv\lib\site-packages\django\core\servers\basehttp.py basehttp.py basehttp log_message 124: "POST /search_config/ HTTP/1.1" 500 62870
ERROR 2018-11-14 10:16:57,561 C:\Users\Administrator\venv\lib\site-packages\django\utils\log.py log.py log log_response 228: Internal Server Error: /search_config/
Traceback (most recent call last):
  File "C:\Users\Administrator\venv\lib\site-packages\django\core\handlers\exception.py", line 34, in inner
    response = get_response(request)
  File "C:\Users\Administrator\venv\lib\site-packages\django\core\handlers\base.py", line 126, in _get_response
    response = self.process_exception_by_middleware(e, request)
  File "C:\Users\Administrator\venv\lib\site-packages\django\core\handlers\base.py", line 124, in _get_response
    response = wrapped_callback(request, *callback_args, **callback_kwargs)
  File "C:\Users\Administrator\AppData\Local\Programs\Python\Python37-32\lib\contextlib.py", line 74, in inner
    return func(*args, **kwds)
  File "D:\项目汇总\仓库管理\trank_\RtMonSys\views\view_store_out.py", line 36, in search_config
    return JsonResponse({"totalDataNumber": totalDataNumber, "data": results})
  File "C:\Users\Administrator\venv\lib\site-packages\django\http\response.py", line 552, in __init__
    'In order to allow non-dict objects to be serialized set the '
TypeError: In order to allow non-dict objects to be serialized set the safe parameter to False.
ERROR 2018-11-14 10:16:57,567 C:\Users\Administrator\venv\lib\site-packages\django\core\servers\basehttp.py basehttp.py basehttp log_message 124: "POST /search_config/ HTTP/1.1" 500 82087
WARNING 2018-11-14 10:17:04,966 C:\Users\Administrator\venv\lib\site-packages\django\core\servers\basehttp.py basehttp.py basehttp log_message 124: "GET /static/resource/element/axios.min.map HTTP/1.1" 404 1714
ERROR 2018-11-14 10:17:13,077 C:\Users\Administrator\venv\lib\site-packages\django\utils\log.py log.py log log_response 228: Internal Server Error: /search_config/
Traceback (most recent call last):
  File "C:\Users\Administrator\venv\lib\site-packages\django\core\handlers\exception.py", line 34, in inner
    response = get_response(request)
  File "C:\Users\Administrator\venv\lib\site-packages\django\core\handlers\base.py", line 126, in _get_response
    response = self.process_exception_by_middleware(e, request)
  File "C:\Users\Administrator\venv\lib\site-packages\django\core\handlers\base.py", line 124, in _get_response
    response = wrapped_callback(request, *callback_args, **callback_kwargs)
  File "C:\Users\Administrator\AppData\Local\Programs\Python\Python37-32\lib\contextlib.py", line 74, in inner
    return func(*args, **kwds)
  File "D:\项目汇总\仓库管理\trank_\RtMonSys\views\view_store_out.py", line 36, in search_config
    return JsonResponse({"totalDataNumber": totalDataNumber, "data": results})
  File "C:\Users\Administrator\venv\lib\site-packages\django\http\response.py", line 552, in __init__
    'In order to allow non-dict objects to be serialized set the '
TypeError: In order to allow non-dict objects to be serialized set the safe parameter to False.
ERROR 2018-11-14 10:17:13,082 C:\Users\Administrator\venv\lib\site-packages\django\core\servers\basehttp.py basehttp.py basehttp log_message 124: "POST /search_config/ HTTP/1.1" 500 82121
ERROR 2018-11-14 10:18:04,065 C:\Users\Administrator\venv\lib\site-packages\django\utils\log.py log.py log log_response 228: Internal Server Error: /search_config/
Traceback (most recent call last):
  File "C:\Users\Administrator\venv\lib\site-packages\django\core\handlers\exception.py", line 34, in inner
    response = get_response(request)
  File "C:\Users\Administrator\venv\lib\site-packages\django\core\handlers\base.py", line 126, in _get_response
    response = self.process_exception_by_middleware(e, request)
  File "C:\Users\Administrator\venv\lib\site-packages\django\core\handlers\base.py", line 124, in _get_response
    response = wrapped_callback(request, *callback_args, **callback_kwargs)
  File "C:\Users\Administrator\AppData\Local\Programs\Python\Python37-32\lib\contextlib.py", line 74, in inner
    return func(*args, **kwds)
  File "D:\项目汇总\仓库管理\trank_\RtMonSys\views\view_store_out.py", line 36, in search_config
    return JsonResponse({"totalDataNumber": totalDataNumber, "data": results})
  File "C:\Users\Administrator\venv\lib\site-packages\django\http\response.py", line 552, in __init__
    'In order to allow non-dict objects to be serialized set the '
TypeError: In order to allow non-dict objects to be serialized set the safe parameter to False.
ERROR 2018-11-14 10:18:04,072 C:\Users\Administrator\venv\lib\site-packages\django\core\servers\basehttp.py basehttp.py basehttp log_message 124: "POST /search_config/ HTTP/1.1" 500 82121
WARNING 2018-11-14 10:20:18,912 C:\Users\Administrator\venv\lib\site-packages\django\core\servers\basehttp.py basehttp.py basehttp log_message 124: "GET /static/resource/element/axios.min.map HTTP/1.1" 404 1714
WARNING 2018-11-14 10:20:23,034 C:\Users\Administrator\venv\lib\site-packages\django\core\servers\basehttp.py basehttp.py basehttp log_message 124: "GET /static/resource/element/axios.min.map HTTP/1.1" 404 1714
WARNING 2018-11-14 10:20:32,488 C:\Users\Administrator\venv\lib\site-packages\django\core\servers\basehttp.py basehttp.py basehttp log_message 124: "GET /static/resource/element/axios.min.map HTTP/1.1" 404 1714
WARNING 2018-11-14 10:20:39,433 C:\Users\Administrator\venv\lib\site-packages\django\core\servers\basehttp.py basehttp.py basehttp log_message 124: "GET /static/resource/element/axios.min.map HTTP/1.1" 404 1714
WARNING 2018-11-14 10:37:59,539 C:\Users\Administrator\venv\lib\site-packages\django\core\servers\basehttp.py basehttp.py basehttp log_message 124: "GET /static/resource/element/axios.min.map HTTP/1.1" 404 1714
WARNING 2018-11-14 11:45:49,206 C:\Users\Administrator\venv\lib\site-packages\django\core\servers\basehttp.py basehttp.py basehttp log_message 124: "GET /static/resource/element/axios.min.map HTTP/1.1" 404 1714
WARNING 2018-11-14 11:46:45,161 C:\Users\Administrator\venv\lib\site-packages\django\core\servers\basehttp.py basehttp.py basehttp log_message 124: "GET /static/resource/element/axios.min.map HTTP/1.1" 404 1714
WARNING 2018-11-14 11:46:59,455 C:\Users\Administrator\venv\lib\site-packages\django\core\servers\basehttp.py basehttp.py basehttp log_message 124: "GET /static/resource/element/axios.min.map HTTP/1.1" 404 1714
WARNING 2018-11-14 11:47:49,170 C:\Users\Administrator\venv\lib\site-packages\django\core\servers\basehttp.py basehttp.py basehttp log_message 124: "GET /static/resource/element/axios.min.map HTTP/1.1" 404 1714
WARNING 2018-11-14 11:47:56,215 C:\Users\Administrator\venv\lib\site-packages\django\core\servers\basehttp.py basehttp.py basehttp log_message 124: "GET /static/resource/element/axios.min.map HTTP/1.1" 404 1714
WARNING 2018-11-15 08:55:46,336 C:\Users\Administrator\venv\lib\site-packages\django\core\servers\basehttp.py basehttp.py basehttp log_message 124: "GET /static/config/config.js HTTP/1.1" 404 1672
WARNING 2018-11-15 08:55:46,638 C:\Users\Administrator\venv\lib\site-packages\django\core\servers\basehttp.py basehttp.py basehttp log_message 124: "GET /static/config/config.js HTTP/1.1" 404 1672
WARNING 2018-11-15 08:56:01,280 C:\Users\Administrator\venv\lib\site-packages\django\utils\log.py log.py log log_response 228: Not Found: /index.html
WARNING 2018-11-15 08:56:01,282 C:\Users\Administrator\venv\lib\site-packages\django\core\servers\basehttp.py basehttp.py basehttp log_message 124: "GET /index.html HTTP/1.1" 404 2754
